Workbook
Name IDX: 'Medicare Enrolments'!$A$3

Sheet Labour - Prices
V1: Year 0 | AE1: Year 1 | AN1: Year 2 | AW1: Year 3 | BF1: Year 4
A2: Jurisdiction | B2: Personnel type | C2: Label | D2: Award | E2: Grade(s) | V2: Base Salary | Y2: Base Salary + Costs | AB2: Base Salary + Costs (hourly) | AE2: Base Salary | AH2: Base Salary + Costs | AK2: Base Salary + Costs (hourly) | AN2: Base Salary | AQ2: Base Salary + Costs | AT2: Base Salary + Costs (hourly) | AW2: Base Salary | AZ2: Base Salary + Costs | BC2: Base Salary + Costs (hourly) | BF2: Base Salary | BI2: Base Salary + Costs | BL2: Base Salary + Costs (hourly)
F3: Distribution desc | G3: References | H3: Rate of Pay (weekly, 38h) desc | I3: Year | J3: Superannuation Rate (%) | K3: Hours per week | L3: Average productive time (%) | M3: Average Penalties % | N3: Public Holiday Penalty % | O3: Private Practice Loading % | P3: Attraction and Retention Allowance % | Q3: Sick Leave % | R3: Professional Development Allowance ($) | S3: Annual Leave Entitlement (Weeks) | T3: Annual Leave Loading (%) | U3: Indexation per annum (%) | V3: LL | W3: Mid-point | X3: UL | Y3: LL | Z3: Mid-point | AA3: UL | AB3: LL | AC3: Mid-point | AD3: UL | AE3: LL | AF3: Mid-point | AG3: UL | AH3: LL | AI3: Mid-point | AJ3: UL | AK3: LL | AL3: Mid-point | AM3: UL | AN3: LL | AO3: Mid-point | AP3: UL | AQ3: LL | AR3: Mid-point | AS3: UL | AT3: LL | AU3: Mid-point | AV3: UL | AW3: LL | AX3: Mid-point | AY3: UL | AZ3: LL | BA3: Mid-point | BB3: UL | BC3: LL | BD3: Mid-point | BE3: UL | BF3: LL | BG3: Mid-point | BH3: UL | BI3: LL | BJ3: Mid-point | BK3: UL | BL3: LL | BM3: Mid-point | BN3: UL
A4: VIC | B4: Lab technician | C4: LT | D4: HPA | E4: 5-7 | F4: normal distro | G4: pp247 HS5-HS7 (July 22) | H4: 1785.7-2257.10 | I4: 2022 | J4: 0.105 | K4: 38 | L4: 1 | M4: 0.1 | N4: 0.035 | O4: 0 | P4: 0 | Q4: 0.046 | R4: 0 | S4: 4 | T4: 0.175 | U4: 0.015 | V4: 79624 | W4: =V4+((X4-V4)/2) -> 94969 | X4: 110314 | Y4: =(V4+(V4*$J4)+(V4*$M4)+(V4*$N4)+(V4*$O4)+(V4*$P4)+(V4*$Q4)+($R4)+(V4*((52+$S4)/52))*(1+$T4))*1/$L4 -> 203151.45 | Z4: =(W4+(W4*$J4)+(W4*$M4)+(W4*$N4)+(W4*$O4)+(W4*$P4)+(W4*$Q4)+($R4)+(W4*((52+$S4)/52))*(1+$T4))*1/$L4 -> 242302.45 | AA4: =(X4+(X4*$J4)+(X4*$M4)+(X4*$N4)+(X4*$O4)+(X4*$P4)+(X4*$Q4)+($R4)+(X4*((52+$S4)/52))*(1+$T4))*1/$L4 -> 281453.44 | AB4: =Y4/52/$K4 -> 102.80944 | AC4: =Z4/52/$K4 -> 122.6227 | AD4: =AA4/52/$K4 -> 142.43595 | AE4: =($V4*(1+(($U4/100)*1))) -> 79635.944 | AF4: =($W4*(1+(($U4/100)*1))) -> 94983.245 | AG4: =($X4*(1+(($U4/100)*1))) -> 110330.55 | AH4: =(AE4+(AE4*$J4)+(AE4*$M4)+(AE4*$N4)+(AE4*$O4)+(AE4*$P4)+(AE4*$Q4)+($R4)+(AE4*((52+$S4)/52))*(1+$T4))*1/$L4 -> 203181.92 | AI4: =(AF4+(AF4*$J4)+(AF4*$M4)+(AF4*$N4)+(AF4*$O4)+(AF4*$P4)+(AF4*$Q4)+($R4)+(AF4*((52+$S4)/52))*(1+$T4))*1/$L4 -> 242338.79 | AJ4: =(AG4+(AG4*$J4)+(AG4*$M4)+(AG4*$N4)+(AG4*$O4)+(AG4*$P4)+(AG4*$Q4)+($R4)+(AG4*((52+$S4)/52))*(1+$T4))*1/$L4 -> 281495.66 | AK4: =AH4/52/$K4 -> 102.82486 | AL4: =AI4/52/$K4 -> 122.64109 | AM4: =AJ4/52/$K4 -> 142.45732 | AN4: =($V4*(1+(($U4/100)*2))) -> 79647.887 | AO4: =($W4*(1+(($U4/100)*2))) -> 94997.491 | AP4: =($X4*(1+(($U4/100)*2))) -> 110347.09 | AQ4: =(AN4+(AN4*$J4)+(AN4*$M4)+(AN4*$N4)+(AN4*$O4)+(AN4*$P4)+(AN4*$Q4)+($R4)+(AN4*((52+$S4)/52))*(1+$T4))*1/$L4 -> 203212.39 | AR4: =(AO4+(AO4*$J4)+(AO4*$M4)+(AO4*$N4)+(AO4*$O4)+(AO4*$P4)+(AO4*$Q4)+($R4)+(AO4*((52+$S4)/52))*(1+$T4))*1/$L4 -> 242375.14 | AS4: =(AP4+(AP4*$J4)+(AP4*$M4)+(AP4*$N4)+(AP4*$O4)+(AP4*$P4)+(AP4*$Q4)+($R4)+(AP4*((52+$S4)/52))*(1+$T4))*1/$L4 -> 281537.88 | AT4: =AQ4/52/$K4 -> 102.84028 | AU4: =AR4/52/$K4 -> 122.65948 | AV4: =AS4/52/$K4 -> 142.47868 | AW4: =($V4*(1+(($U4/100)*3))) -> 79659.831 | AX4: =($W4*(1+(($U4/100)*3))) -> 95011.736 | AY4: =($X4*(1+(($U4/100)*3))) -> 110363.64 | AZ4: =(AW4+(AW4*$J4)+(AW4*$M4)+(AW4*$N4)+(AW4*$O4)+(AW4*$P4)+(AW4*$Q4)+($R4)+(AW4*((52+$S4)/52))*(1+$T4))*1/$L4 -> 203242.87 | BA4: =(AX4+(AX4*$J4)+(AX4*$M4)+(AX4*$N4)+(AX4*$O4)+(AX4*$P4)+(AX4*$Q4)+($R4)+(AX4*((52+$S4)/52))*(1+$T4))*1/$L4 -> 242411.48 | BB4: =(AY4+(AY4*$J4)+(AY4*$M4)+(AY4*$N4)+(AY4*$O4)+(AY4*$P4)+(AY4*$Q4)+($R4)+(AY4*((52+$S4)/52))*(1+$T4))*1/$L4 -> 281580.1 | BC4: =AZ4/52/$K4 -> 102.8557 | BD4: =BA4/52/$K4 -> 122.67788 | BE4: =BB4/52/$K4 -> 142.50005 | BF4: =($V4*(1+(($U4/100)*4))) -> 79671.774 | BG4: =($W4*(1+(($U4/100)*4))) -> 95025.981 | BH4: =($X4*(1+(($U4/100)*4))) -> 110380.19 | BI4: =(BF4+(BF4*$J4)+(BF4*$M4)+(BF4*$N4)+(BF4*$O4)+(BF4*$P4)+(BF4*$Q4)+($R4)+(BF4*((52+$S4)/52))*(1+$T4))*1/$L4 -> 203273.34 | BJ4: =(BG4+(BG4*$J4)+(BG4*$M4)+(BG4*$N4)+(BG4*$O4)+(BG4*$P4)+(BG4*$Q4)+($R4)+(BG4*((52+$S4)/52))*(1+$T4))*1/$L4 -> 242447.83 | BK4: =(BH4+(BH4*$J4)+(BH4*$M4)+(BH4*$N4)+(BH4*$O4)+(BH4*$P4)+(BH4*$Q4)+($R4)+(BH4*((52+$S4)/52))*(1+$T4))*1/$L4 -> 281622.31 | BL4: =BI4/52/$K4 -> 102.87112 | BM4: =BJ4/52/$K4 -> 122.69627 | BN4: =BK4/52/$K4 -> 142.52141
A5: VIC | B5: Medical scientist | C5: MS | D5: MSEBA | E5: MS1-4(RX4)-MS4-5(RZ7) | F5: skewed normal | G5: pp111 VPHS 2017-21 RX1-RZ7 | H5: 1131.30-2622.00 | I5: 2023 | J5: 0.105 | K5: 38 | L5: 1 | M5: 0.1 | N5: 0.035 | O5: 0 | P5: 0 | Q5: 0.046 | R5: 0 | S5: 5 | T5: 0.175 | U5: 0.015 | V5: =1177*52 -> 61204 | W5: =V5+((X5-V5)/2) -> 101878.4 | X5: =2741.4*52 -> 142552.8 | Y5: =(V5+(V5*$J5)+(V5*$M5)+(V5*$N5)+(V5*$O5)+(V5*$P5)+(V5*$Q5)+($R5)+(V5*((52+$S5)/52))*(1+$T5))*1/$L5 -> 157537.92 | Z5: =(W5+(W5*$J5)+(W5*$M5)+(W5*$N5)+(W5*$O5)+(W5*$P5)+(W5*$Q5)+($R5)+(W5*((52+$S5)/52))*(1+$T5))*1/$L5 -> 262233.04 | AA5: =(X5+(X5*$J5)+(X5*$M5)+(X5*$N5)+(X5*$O5)+(X5*$P5)+(X5*$Q5)+($R5)+(X5*((52+$S5)/52))*(1+$T5))*1/$L5 -> 366928.17 | AB5: =Y5/52/$K5 -> 79.725668 | AC5: =Z5/52/$K5 -> 132.70903 | AD5: =AA5/52/$K5 -> 185.69239 | AE5: =($V5*(1+(($U5/100)*1))) -> 61213.181 | AF5: =($W5*(1+(($U5/100)*1))) -> 101893.68 | AG5: =($X5*(1+(($U5/100)*1))) -> 142574.18 | AH5: =(AE5+(AE5*$J5)+(AE5*$M5)+(AE5*$N5)+(AE5*$O5)+(AE5*$P5)+(AE5*$Q5)+($R5)+(AE5*((52+$S5)/52))*(1+$T5))*1/$L5 -> 157561.55 | AI5: =(AF5+(AF5*$J5)+(AF5*$M5)+(AF5*$N5)+(AF5*$O5)+(AF5*$P5)+(AF5*$Q5)+($R5)+(AF5*((52+$S5)/52))*(1+$T5))*1/$L5 -> 262272.38 | AJ5: =(AG5+(AG5*$J5)+(AG5*$M5)+(AG5*$N5)+(AG5*$O5)+(AG5*$P5)+(AG5*$Q5)+($R5)+(AG5*((52+$S5)/52))*(1+$T5))*1/$L5 -> 366983.21 | AK5: =AH5/52/$K5 -> 79.737626 | AL5: =AI5/52/$K5 -> 132.72894 | AM5: =AJ5/52/$K5 -> 185.72025 | AN5: =($V5*(1+(($U5/100)*2))) -> 61222.361 | AO5: =($W5*(1+(($U5/100)*2))) -> 101908.96 | AP5: =($X5*(1+(($U5/100)*2))) -> 142595.57 | AQ5: =(AN5+(AN5*$J5)+(AN5*$M5)+(AN5*$N5)+(AN5*$O5)+(AN5*$P5)+(AN5*$Q5)+($R5)+(AN5*((52+$S5)/52))*(1+$T5))*1/$L5 -> 157585.18 | AR5: =(AO5+(AO5*$J5)+(AO5*$M5)+(AO5*$N5)+(AO5*$O5)+(AO5*$P5)+(AO5*$Q5)+($R5)+(AO5*((52+$S5)/52))*(1+$T5))*1/$L5 -> 262311.71 | AS5: =(AP5+(AP5*$J5)+(AP5*$M5)+(AP5*$N5)+(AP5*$O5)+(AP5*$P5)+(AP5*$Q5)+($R5)+(AP5*((52+$S5)/52))*(1+$T5))*1/$L5 -> 367038.24 | AT5: =AQ5/52/$K5 -> 79.749585 | AU5: =AR5/52/$K5 -> 132.74884 | AV5: =AS5/52/$K5 -> 185.7481 | AW5: =($V5*(1+(($U5/100)*3))) -> 61231.542 | AX5: =($W5*(1+(($U5/100)*3))) -> 101924.25 | AY5: =($X5*(1+(($U5/100)*3))) -> 142616.95 | AZ5: =(AW5+(AW5*$J5)+(AW5*$M5)+(AW5*$N5)+(AW5*$O5)+(AW5*$P5)+(AW5*$Q5)+($R5)+(AW5*((52+$S5)/52))*(1+$T5))*1/$L5 -> 157608.81 | BA5: =(AX5+(AX5*$J5)+(AX5*$M5)+(AX5*$N5)+(AX5*$O5)+(AX5*$P5)+(AX5*$Q5)+($R5)+(AX5*((52+$S5)/52))*(1+$T5))*1/$L5 -> 262351.05 | BB5: =(AY5+(AY5*$J5)+(AY5*$M5)+(AY5*$N5)+(AY5*$O5)+(AY5*$P5)+(AY5*$Q5)+($R5)+(AY5*((52+$S5)/52))*(1+$T5))*1/$L5 -> 367093.28 | BC5: =AZ5/52/$K5 -> 79.761544 | BD5: =BA5/52/$K5 -> 132.76875 | BE5: =BB5/52/$K5 -> 185.77595 | BF5: =($V5*(1+(($U5/100)*4))) -> 61240.722 | BG5: =($W5*(1+(($U5/100)*4))) -> 101939.53 | BH5: =($X5*(1+(($U5/100)*4))) -> 142638.33 | BI5: =(BF5+(BF5*$J5)+(BF5*$M5)+(BF5*$N5)+(BF5*$O5)+(BF5*$P5)+(BF5*$Q5)+($R5)+(BF5*((52+$S5)/52))*(1+$T5))*1/$L5 -> 157632.44 | BJ5: =(BG5+(BG5*$J5)+(BG5*$M5)+(BG5*$N5)+(BG5*$O5)+(BG5*$P5)+(BG5*$Q5)+($R5)+(BG5*((52+$S5)/52))*(1+$T5))*1/$L5 -> 262390.38 | BK5: =(BH5+(BH5*$J5)+(BH5*$M5)+(BH5*$N5)+(BH5*$O5)+(BH5*$P5)+(BH5*$Q5)+($R5)+(BH5*((52+$S5)/52))*(1+$T5))*1/$L5 -> 367148.32 | BL5: =BI5/52/$K5 -> 79.773503 | BM5: =BJ5/52/$K5 -> 132.78865 | BN5: =BK5/52/$K5 -> 185.80381
A6: VIC | B6: Admin staff | C6: AS | D6: HPA | E6: 3-5 | G6: pp247 HS5-HS7 (July 22) | H6: 1785.7-2257.10 | I6: 2022 | J6: 0.105 | K6: 38 | L6: 1 | M6: 0.1 | N6: 0.035 | O6: 0 | P6: 0 | Q6: 0.046 | R6: 0 | S6: 4 | T6: 0.175 | U6: 0.015 | V6: 63701 | W6: =V6+((X6-V6)/2) -> 77580.5 | X6: 91460 | Y6: =(V6+(V6*$J6)+(V6*$M6)+(V6*$N6)+(V6*$O6)+(V6*$P6)+(V6*$Q6)+($R6)+(V6*((52+$S6)/52))*(1+$T6))*1/$L6 -> 162525.75 | Z6: =(W6+(W6*$J6)+(W6*$M6)+(W6*$N6)+(W6*$O6)+(W6*$P6)+(W6*$Q6)+($R6)+(W6*((52+$S6)/52))*(1+$T6))*1/$L6 -> 197937.69 | AA6: =(X6+(X6*$J6)+(X6*$M6)+(X6*$N6)+(X6*$O6)+(X6*$P6)+(X6*$Q6)+($R6)+(X6*((52+$S6)/52))*(1+$T6))*1/$L6 -> 233349.64 | AB6: =Y6/52/$K6 -> 82.249874 | AC6: =Z6/52/$K6 -> 100.1709 | AD6: =AA6/52/$K6 -> 118.09192 | AE6: =($V6*(1+(($U6/100)*1))) -> 63710.555 | AF6: =($W6*(1+(($U6/100)*1))) -> 77592.137 | AG6: =($X6*(1+(($U6/100)*1))) -> 91473.719 | AH6: =(AE6+(AE6*$J6)+(AE6*$M6)+(AE6*$N6)+(AE6*$O6)+(AE6*$P6)+(AE6*$Q6)+($R6)+(AE6*((52+$S6)/52))*(1+$T6))*1/$L6 -> 162550.13 | AI6: =(AF6+(AF6*$J6)+(AF6*$M6)+(AF6*$N6)+(AF6*$O6)+(AF6*$P6)+(AF6*$Q6)+($R6)+(AF6*((52+$S6)/52))*(1+$T6))*1/$L6 -> 197967.38 | AJ6: =(AG6+(AG6*$J6)+(AG6*$M6)+(AG6*$N6)+(AG6*$O6)+(AG6*$P6)+(AG6*$Q6)+($R6)+(AG6*((52+$S6)/52))*(1+$T6))*1/$L6 -> 233384.64 | AK6: =AH6/52/$K6 -> 82.262212 | AL6: =AI6/52/$K6 -> 100.18592 | AM6: =AJ6/52/$K6 -> 118.10964 | AN6: =($V6*(1+(($U6/100)*2))) -> 63720.11 | AO6: =($W6*(1+(($U6/100)*2))) -> 77603.774 | AP6: =($X6*(1+(($U6/100)*2))) -> 91487.438 | AQ6: =(AN6+(AN6*$J6)+(AN6*$M6)+(AN6*$N6)+(AN6*$O6)+(AN6*$P6)+(AN6*$Q6)+($R6)+(AN6*((52+$S6)/52))*(1+$T6))*1/$L6 -> 162574.51 | AR6: =(AO6+(AO6*$J6)+(AO6*$M6)+(AO6*$N6)+(AO6*$O6)+(AO6*$P6)+(AO6*$Q6)+($R6)+(AO6*((52+$S6)/52))*(1+$T6))*1/$L6 -> 197997.08 | AS6: =(AP6+(AP6*$J6)+(AP6*$M6)+(AP6*$N6)+(AP6*$O6)+(AP6*$P6)+(AP6*$Q6)+($R6)+(AP6*((52+$S6)/52))*(1+$T6))*1/$L6 -> 233419.64 | AT6: =AQ6/52/$K6 -> 82.274549 | AU6: =AR6/52/$K6 -> 100.20095 | AV6: =AS6/52/$K6 -> 118.12735 | AW6: =($V6*(1+(($U6/100)*3))) -> 63729.665 | AX6: =($W6*(1+(($U6/100)*3))) -> 77615.411 | AY6: =($X6*(1+(($U6/100)*3))) -> 91501.157 | AZ6: =(AW6+(AW6*$J6)+(AW6*$M6)+(AW6*$N6)+(AW6*$O6)+(AW6*$P6)+(AW6*$Q6)+($R6)+(AW6*((52+$S6)/52))*(1+$T6))*1/$L6 -> 162598.89 | BA6: =(AX6+(AX6*$J6)+(AX6*$M6)+(AX6*$N6)+(AX6*$O6)+(AX6*$P6)+(AX6*$Q6)+($R6)+(AX6*((52+$S6)/52))*(1+$T6))*1/$L6 -> 198026.77 | BB6: =(AY6+(AY6*$J6)+(AY6*$M6)+(AY6*$N6)+(AY6*$O6)+(AY6*$P6)+(AY6*$Q6)+($R6)+(AY6*((52+$S6)/52))*(1+$T6))*1/$L6 -> 233454.64 | BC6: =AZ6/52/$K6 -> 82.286887 | BD6: =BA6/52/$K6 -> 100.21597 | BE6: =BB6/52/$K6 -> 118.14506 | BF6: =($V6*(1+(($U6/100)*4))) -> 63739.221 | BG6: =($W6*(1+(($U6/100)*4))) -> 77627.048 | BH6: =($X6*(1+(($U6/100)*4))) -> 91514.876 | BI6: =(BF6+(BF6*$J6)+(BF6*$M6)+(BF6*$N6)+(BF6*$O6)+(BF6*$P6)+(BF6*$Q6)+($R6)+(BF6*((52+$S6)/52))*(1+$T6))*1/$L6 -> 162623.27 | BJ6: =(BG6+(BG6*$J6)+(BG6*$M6)+(BG6*$N6)+(BG6*$O6)+(BG6*$P6)+(BG6*$Q6)+($R6)+(BG6*((52+$S6)/52))*(1+$T6))*1/$L6 -> 198056.46 | BK6: =(BH6+(BH6*$J6)+(BH6*$M6)+(BH6*$N6)+(BH6*$O6)+(BH6*$P6)+(BH6*$Q6)+($R6)+(BH6*((52+$S6)/52))*(1+$T6))*1/$L6 -> 233489.65 | BL6: =BI6/52/$K6 -> 82.299224 | BM6: =BJ6/52/$K6 -> 100.231 | BN6: =BK6/52/$K6 -> 118.16278
A7: VIC | B7: Bioinformatics staff | C7: BI | D7: MCRI Professional and Administrative Salaries | E7: 5-8 | G7: pp247 HS5-HS7 (July 22) | H7: 1785.7-2525.90 | I7: 2022 | J7: 0.105 | K7: 38 | L7: 1 | M7: 0.1 | N7: 0.035 | O7: 0 | P7: 0 | Q7: 0.046 | R7: 0 | S7: 4 | T7: 0.175 | U7: 0.015 | V7: 79624 | W7: =V7+((X7-V7)/2) -> 101861 | X7: 124098 | Y7: =(V7+(V7*$J7)+(V7*$M7)+(V7*$N7)+(V7*$O7)+(V7*$P7)+(V7*$Q7)+($R7)+(V7*((52+$S7)/52))*(1+$T7))*1/$L7 -> 203151.45 | Z7: =(W7+(W7*$J7)+(W7*$M7)+(W7*$N7)+(W7*$O7)+(W7*$P7)+(W7*$Q7)+($R7)+(W7*((52+$S7)/52))*(1+$T7))*1/$L7 -> 259886.59 | AA7: =(X7+(X7*$J7)+(X7*$M7)+(X7*$N7)+(X7*$O7)+(X7*$P7)+(X7*$Q7)+($R7)+(X7*((52+$S7)/52))*(1+$T7))*1/$L7 -> 316621.73 | AB7: =Y7/52/$K7 -> 102.80944 | AC7: =Z7/52/$K7 -> 131.52155 | AD7: =AA7/52/$K7 -> 160.23367 | AE7: =($V7*(1+(($U7/100)*1))) -> 79635.944 | AF7: =($W7*(1+(($U7/100)*1))) -> 101876.28 | AG7: =($X7*(1+(($U7/100)*1))) -> 124116.61 | AH7: =(AE7+(AE7*$J7)+(AE7*$M7)+(AE7*$N7)+(AE7*$O7)+(AE7*$P7)+(AE7*$Q7)+($R7)+(AE7*((52+$S7)/52))*(1+$T7))*1/$L7 -> 203181.92 | AI7: =(AF7+(AF7*$J7)+(AF7*$M7)+(AF7*$N7)+(AF7*$O7)+(AF7*$P7)+(AF7*$Q7)+($R7)+(AF7*((52+$S7)/52))*(1+$T7))*1/$L7 -> 259925.57 | AJ7: =(AG7+(AG7*$J7)+(AG7*$M7)+(AG7*$N7)+(AG7*$O7)+(AG7*$P7)+(AG7*$Q7)+($R7)+(AG7*((52+$S7)/52))*(1+$T7))*1/$L7 -> 316669.22 | AK7: =AH7/52/$K7 -> 102.82486 | AL7: =AI7/52/$K7 -> 131.54128 | AM7: =AJ7/52/$K7 -> 160.2577 | AN7: =($V7*(1+(($U7/100)*2))) -> 79647.887 | AO7: =($W7*(1+(($U7/100)*2))) -> 101891.56 | AP7: =($X7*(1+(($U7/100)*2))) -> 124135.23 | AQ7: =(AN7+(AN7*$J7)+(AN7*$M7)+(AN7*$N7)+(AN7*$O7)+(AN7*$P7)+(AN7*$Q7)+($R7)+(AN7*((52+$S7)/52))*(1+$T7))*1/$L7 -> 203212.39 | AR7: =(AO7+(AO7*$J7)+(AO7*$M7)+(AO7*$N7)+(AO7*$O7)+(AO7*$P7)+(AO7*$Q7)+($R7)+(AO7*((52+$S7)/52))*(1+$T7))*1/$L7 -> 259964.55 | AS7: =(AP7+(AP7*$J7)+(AP7*$M7)+(AP7*$N7)+(AP7*$O7)+(AP7*$P7)+(AP7*$Q7)+($R7)+(AP7*((52+$S7)/52))*(1+$T7))*1/$L7 -> 316716.71 | AT7: =AQ7/52/$K7 -> 102.84028 | AU7: =AR7/52/$K7 -> 131.56101 | AV7: =AS7/52/$K7 -> 160.28174 | AW7: =($V7*(1+(($U7/100)*3))) -> 79659.831 | AX7: =($W7*(1+(($U7/100)*3))) -> 101906.84 | AY7: =($X7*(1+(($U7/100)*3))) -> 124153.84 | AZ7: =(AW7+(AW7*$J7)+(AW7*$M7)+(AW7*$N7)+(AW7*$O7)+(AW7*$P7)+(AW7*$Q7)+($R7)+(AW7*((52+$S7)/52))*(1+$T7))*1/$L7 -> 203242.87 | BA7: =(AX7+(AX7*$J7)+(AX7*$M7)+(AX7*$N7)+(AX7*$O7)+(AX7*$P7)+(AX7*$Q7)+($R7)+(AX7*((52+$S7)/52))*(1+$T7))*1/$L7 -> 260003.54 | BB7: =(AY7+(AY7*$J7)+(AY7*$M7)+(AY7*$N7)+(AY7*$O7)+(AY7*$P7)+(AY7*$Q7)+($R7)+(AY7*((52+$S7)/52))*(1+$T7))*1/$L7 -> 316764.21 | BC7: =AZ7/52/$K7 -> 102.8557 | BD7: =BA7/52/$K7 -> 131.58074 | BE7: =BB7/52/$K7 -> 160.30577 | BF7: =($V7*(1+(($U7/100)*4))) -> 79671.774 | BG7: =($W7*(1+(($U7/100)*4))) -> 101922.12 | BH7: =($X7*(1+(($U7/100)*4))) -> 124172.46 | BI7: =(BF7+(BF7*$J7)+(BF7*$M7)+(BF7*$N7)+(BF7*$O7)+(BF7*$P7)+(BF7*$Q7)+($R7)+(BF7*((52+$S7)/52))*(1+$T7))*1/$L7 -> 203273.34 | BJ7: =(BG7+(BG7*$J7)+(BG7*$M7)+(BG7*$N7)+(BG7*$O7)+(BG7*$P7)+(BG7*$Q7)+($R7)+(BG7*((52+$S7)/52))*(1+$T7))*1/$L7 -> 260042.52 | BK7: =(BH7+(BH7*$J7)+(BH7*$M7)+(BH7*$N7)+(BH7*$O7)+(BH7*$P7)+(BH7*$Q7)+($R7)+(BH7*((52+$S7)/52))*(1+$T7))*1/$L7 -> 316811.7 | BL7: =BI7/52/$K7 -> 102.87112 | BM7: =BJ7/52/$K7 -> 131.60047 | BN7: =BK7/52/$K7 -> 160.32981
A8: VIC | B8: Pathologists | C8: MP | D8: MEDICAL SPECIALISTS (VICTORIAN PUBLIC HEALTH SECTOR) (AMA VICTORIA/ASMOF) (SINGLE INTEREST EMPLOYERS) ENTERPRISE AGREEMENT 2022 – 2026 | E8: Assume year 9, full time | F8: rightward skewed | G8: - | H8: 6420.1-7383.20 | I8: 2022 | J8: 0.105 | K8: 38 | L8: 1 | M8: 0 | N8: 0.035 | O8: 0 | P8: 0 | Q8: 0.046 | R8: 29000.16 | S8: 4 | T8: 0.175 | U8: 0.015 | V8: =4797.5*52 -> 249470 | W8: =V8+((X8-V8)/2) -> 296247.9 | X8: =6596.65*52 -> 343025.8 | Y8: =(V8+(V8*$J8)+(V8*$M8)+(V8*$N8)+(V8*$O8)+(V8*$P8)+(V8*$Q8)+($R8)+(V8*((52+$S8)/52))*(1+$T8))*1/$L8 -> 640547.08 | Z8: =(W8+(W8*$J8)+(W8*$M8)+(W8*$N8)+(W8*$O8)+(W8*$P8)+(W8*$Q8)+($R8)+(W8*((52+$S8)/52))*(1+$T8))*1/$L8 -> 755217.7 | AA8: =(X8+(X8*$J8)+(X8*$M8)+(X8*$N8)+(X8*$O8)+(X8*$P8)+(X8*$Q8)+($R8)+(X8*((52+$S8)/52))*(1+$T8))*1/$L8 -> 869888.33 | AB8: =Y8/52/$K8 -> 324.1635 | AC8: =Z8/52/$K8 -> 382.19519 | AD8: =AA8/52/$K8 -> 440.22689 | AE8: =($V8*(1+(($U8/100)*1))) -> 249507.42 | AF8: =($W8*(1+(($U8/100)*1))) -> 296292.34 | AG8: =($X8*(1+(($U8/100)*1))) -> 343077.25 | AH8: =(AE8+(AE8*$J8)+(AE8*$M8)+(AE8*$N8)+(AE8*$O8)+(AE8*$P8)+(AE8*$Q8)+($R8)+(AE8*((52+$S8)/52))*(1+$T8))*1/$L8 -> 640638.81 | AI8: =(AF8+(AF8*$J8)+(AF8*$M8)+(AF8*$N8)+(AF8*$O8)+(AF8*$P8)+(AF8*$Q8)+($R8)+(AF8*((52+$S8)/52))*(1+$T8))*1/$L8 -> 755326.64 | AJ8: =(AG8+(AG8*$J8)+(AG8*$M8)+(AG8*$N8)+(AG8*$O8)+(AG8*$P8)+(AG8*$Q8)+($R8)+(AG8*((52+$S8)/52))*(1+$T8))*1/$L8 -> 870014.46 | AK8: =AH8/52/$K8 -> 324.20993 | AL8: =AI8/52/$K8 -> 382.25032 | AM8: =AJ8/52/$K8 -> 440.29072 | AN8: =($V8*(1+(($U8/100)*2))) -> 249544.84 | AO8: =($W8*(1+(($U8/100)*2))) -> 296336.77 | AP8: =($X8*(1+(($U8/100)*2))) -> 343128.71 | AQ8: =(AN8+(AN8*$J8)+(AN8*$M8)+(AN8*$N8)+(AN8*$O8)+(AN8*$P8)+(AN8*$Q8)+($R8)+(AN8*((52+$S8)/52))*(1+$T8))*1/$L8 -> 640730.54 | AR8: =(AO8+(AO8*$J8)+(AO8*$M8)+(AO8*$N8)+(AO8*$O8)+(AO8*$P8)+(AO8*$Q8)+($R8)+(AO8*((52+$S8)/52))*(1+$T8))*1/$L8 -> 755435.57 | AS8: =(AP8+(AP8*$J8)+(AP8*$M8)+(AP8*$N8)+(AP8*$O8)+(AP8*$P8)+(AP8*$Q8)+($R8)+(AP8*((52+$S8)/52))*(1+$T8))*1/$L8 -> 870140.6 | AT8: =AQ8/52/$K8 -> 324.25635 | AU8: =AR8/52/$K8 -> 382.30545 | AV8: =AS8/52/$K8 -> 440.35455 | AW8: =($V8*(1+(($U8/100)*3))) -> 249582.26 | AX8: =($W8*(1+(($U8/100)*3))) -> 296381.21 | AY8: =($X8*(1+(($U8/100)*3))) -> 343180.16 | AZ8: =(AW8+(AW8*$J8)+(AW8*$M8)+(AW8*$N8)+(AW8*$O8)+(AW8*$P8)+(AW8*$Q8)+($R8)+(AW8*((52+$S8)/52))*(1+$T8))*1/$L8 -> 640822.28 | BA8: =(AX8+(AX8*$J8)+(AX8*$M8)+(AX8*$N8)+(AX8*$O8)+(AX8*$P8)+(AX8*$Q8)+($R8)+(AX8*((52+$S8)/52))*(1+$T8))*1/$L8 -> 755544.5 | BB8: =(AY8+(AY8*$J8)+(AY8*$M8)+(AY8*$N8)+(AY8*$O8)+(AY8*$P8)+(AY8*$Q8)+($R8)+(AY8*((52+$S8)/52))*(1+$T8))*1/$L8 -> 870266.73 | BC8: =AZ8/52/$K8 -> 324.30277 | BD8: =BA8/52/$K8 -> 382.36058 | BE8: =BB8/52/$K8 -> 440.41838 | BF8: =($V8*(1+(($U8/100)*4))) -> 249619.68 | BG8: =($W8*(1+(($U8/100)*4))) -> 296425.65 | BH8: =($X8*(1+(($U8/100)*4))) -> 343231.62 | BI8: =(BF8+(BF8*$J8)+(BF8*$M8)+(BF8*$N8)+(BF8*$O8)+(BF8*$P8)+(BF8*$Q8)+($R8)+(BF8*((52+$S8)/52))*(1+$T8))*1/$L8 -> 640914.01 | BJ8: =(BG8+(BG8*$J8)+(BG8*$M8)+(BG8*$N8)+(BG8*$O8)+(BG8*$P8)+(BG8*$Q8)+($R8)+(BG8*((52+$S8)/52))*(1+$T8))*1/$L8 -> 755653.43 | BK8: =(BH8+(BH8*$J8)+(BH8*$M8)+(BH8*$N8)+(BH8*$O8)+(BH8*$P8)+(BH8*$Q8)+($R8)+(BH8*((52+$S8)/52))*(1+$T8))*1/$L8 -> 870392.86 | BL8: =BI8/52/$K8 -> 324.34919 | BM8: =BJ8/52/$K8 -> 382.41571 | BN8: =BK8/52/$K8 -> 440.48222
A10: SA | B10: Lab technician | C10: LT | D10: S.A. PUBLIC SECTOR SALARIED EMPLOYEES INTERIM AWARD | E10: TG0-1 - TGO-3 | G10: SA Health Costing Table | I10: 2022 | J10: 0.105 | K10: 37.5 | L10: 1 | M10: 0.1 | N10: 0.035 | O10: 0 | P10: 0 | Q10: 0.046 | R10: 0 | S10: 4 | T10: 0 | U10: 0.015 | V10: 54364 | W10: =V10+((X10-V10)/2) -> 77673 | X10: 100982 | Y10: =(V10+(V10*$J10)+(V10*$M10)+(V10*$N10)+(V10*$O10)+(V10*$P10)+(V10*$Q10)+($R10)+(V10*((52+$S10)/52))*(1+$T10))*1/$L10 -> 128457.95 | Z10: =(W10+(W10*$J10)+(W10*$M10)+(W10*$N10)+(W10*$O10)+(W10*$P10)+(W10*$Q10)+($R10)+(W10*((52+$S10)/52))*(1+$T10))*1/$L10 -> 183535.32 | AA10: =(X10+(X10*$J10)+(X10*$M10)+(X10*$N10)+(X10*$O10)+(X10*$P10)+(X10*$Q10)+($R10)+(X10*((52+$S10)/52))*(1+$T10))*1/$L10 -> 238612.7 | AB10: =Y10/52/$K10 -> 65.875872 | AC10: =Z10/52/$K10 -> 94.120679 | AD10: =AA10/52/$K10 -> 122.36549 | AE10: =($V10*(1+(($U10/100)*1))) -> 54372.155 | AF10: =($W10*(1+(($U10/100)*1))) -> 77684.651 | AG10: =($X10*(1+(($U10/100)*1))) -> 100997.15 | AH10: =(AE10+(AE10*$J10)+(AE10*$M10)+(AE10*$N10)+(AE10*$O10)+(AE10*$P10)+(AE10*$Q10)+($R10)+(AE10*((52+$S10)/52))*(1+$T10))*1/$L10 -> 128477.22 | AI10: =(AF10+(AF10*$J10)+(AF10*$M10)+(AF10*$N10)+(AF10*$O10)+(AF10*$P10)+(AF10*$Q10)+($R10)+(AF10*((52+$S10)/52))*(1+$T10))*1/$L10 -> 183562.85 | AJ10: =(AG10+(AG10*$J10)+(AG10*$M10)+(AG10*$N10)+(AG10*$O10)+(AG10*$P10)+(AG10*$Q10)+($R10)+(AG10*((52+$S10)/52))*(1+$T10))*1/$L10 -> 238648.49 | AK10: =AH10/52/$K10 -> 65.885753 | AL10: =AI10/52/$K10 -> 94.134797 | AM10: =AJ10/52/$K10 -> 122.38384 | AN10: =($V10*(1+(($U10/100)*2))) -> 54380.309 | AO10: =($W10*(1+(($U10/100)*2))) -> 77696.302 | AP10: =($X10*(1+(($U10/100)*2))) -> 101012.29 | AQ10: =(AN10+(AN10*$J10)+(AN10*$M10)+(AN10*$N10)+(AN10*$O10)+(AN10*$P10)+(AN10*$Q10)+($R10)+(AN10*((52+$S10)/52))*(1+$T10))*1/$L10 -> 128496.49 | AR10: =(AO10+(AO10*$J10)+(AO10*$M10)+(AO10*$N10)+(AO10*$O10)+(AO10*$P10)+(AO10*$Q10)+($R10)+(AO10*((52+$S10)/52))*(1+$T10))*1/$L10 -> 183590.38 | AS10: =(AP10+(AP10*$J10)+(AP10*$M10)+(AP10*$N10)+(AP10*$O10)+(AP10*$P10)+(AP10*$Q10)+($R10)+(AP10*((52+$S10)/52))*(1+$T10))*1/$L10 -> 238684.28 | AT10: =AQ10/52/$K10 -> 65.895635 | AU10: =AR10/52/$K10 -> 94.148915 | AV10: =AS10/52/$K10 -> 122.4022 | AW10: =($V10*(1+(($U10/100)*3))) -> 54388.464 | AX10: =($W10*(1+(($U10/100)*3))) -> 77707.953 | AY10: =($X10*(1+(($U10/100)*3))) -> 101027.44 | AZ10: =(AW10+(AW10*$J10)+(AW10*$M10)+(AW10*$N10)+(AW10*$O10)+(AW10*$P10)+(AW10*$Q10)+($R10)+(AW10*((52+$S10)/52))*(1+$T10))*1/$L10 -> 128515.76 | BA10: =(AX10+(AX10*$J10)+(AX10*$M10)+(AX10*$N10)+(AX10*$O10)+(AX10*$P10)+(AX10*$Q10)+($R10)+(AX10*((52+$S10)/52))*(1+$T10))*1/$L10 -> 183617.92 | BB10: =(AY10+(AY10*$J10)+(AY10*$M10)+(AY10*$N10)+(AY10*$O10)+(AY10*$P10)+(AY10*$Q10)+($R10)+(AY10*((52+$S10)/52))*(1+$T10))*1/$L10 -> 238720.07 | BC10: =AZ10/52/$K10 -> 65.905516 | BD10: =BA10/52/$K10 -> 94.163033 | BE10: =BB10/52/$K10 -> 122.42055 | BF10: =($V10*(1+(($U10/100)*4))) -> 54396.618 | BG10: =($W10*(1+(($U10/100)*4))) -> 77719.604 | BH10: =($X10*(1+(($U10/100)*4))) -> 101042.59 | BI10: =(BF10+(BF10*$J10)+(BF10*$M10)+(BF10*$N10)+(BF10*$O10)+(BF10*$P10)+(BF10*$Q10)+($R10)+(BF10*((52+$S10)/52))*(1+$T10))*1/$L10 -> 128535.02 | BJ10: =(BG10+(BG10*$J10)+(BG10*$M10)+(BG10*$N10)+(BG10*$O10)+(BG10*$P10)+(BG10*$Q10)+($R10)+(BG10*((52+$S10)/52))*(1+$T10))*1/$L10 -> 183645.45 | BK10: =(BH10+(BH10*$J10)+(BH10*$M10)+(BH10*$N10)+(BH10*$O10)+(BH10*$P10)+(BH10*$Q10)+($R10)+(BH10*((52+$S10)/52))*(1+$T10))*1/$L10 -> 238755.87 | BL10: =BI10/52/$K10 -> 65.915397 | BM10: =BJ10/52/$K10 -> 94.177151 | BN10: =BK10/52/$K10 -> 122.43891
A11: SA | B11: Medical scientist | C11: MS | D11: MEDICAL SCIENTISTS (SOUTH AUSTRALIAN PUBLIC SECTOR) AWARD | E11: MS1 - MS4 | F11: - | G11: pp38 (Schedule 4, pg 1) | H11: 1145.45-2310.89 | I11: 2022 | J11: 0.105 | K11: 37.5 | L11: 1 | M11: 0.1 | N11: 0.035 | O11: 0 | P11: 0 | Q11: 0.046 | R11: 0 | S11: 5 | T11: 0 | U11: 0.015 | V11: 66386 | W11: =V11+((X11-V11)/2) -> 104238 | X11: 142090 | Y11: =(V11+(V11*$J11)+(V11*$M11)+(V11*$N11)+(V11*$O11)+(V11*$P11)+(V11*$Q11)+($R11)+(V11*((52+$S11)/52))*(1+$T11))*1/$L11 -> 158141.67 | Z11: =(W11+(W11*$J11)+(W11*$M11)+(W11*$N11)+(W11*$O11)+(W11*$P11)+(W11*$Q11)+($R11)+(W11*((52+$S11)/52))*(1+$T11))*1/$L11 -> 248310.95 | AA11: =(X11+(X11*$J11)+(X11*$M11)+(X11*$N11)+(X11*$O11)+(X11*$P11)+(X11*$Q11)+($R11)+(X11*((52+$S11)/52))*(1+$T11))*1/$L11 -> 338480.24 | AB11: =Y11/52/$K11 -> 81.09829 | AC11: =Z11/52/$K11 -> 127.33895 | AD11: =AA11/52/$K11 -> 173.57961 | AE11: =($V11*(1+(($U11/100)*1))) -> 66395.958 | AF11: =($W11*(1+(($U11/100)*1))) -> 104253.64 | AG11: =($X11*(1+(($U11/100)*1))) -> 142111.31 | AH11: =(AE11+(AE11*$J11)+(AE11*$M11)+(AE11*$N11)+(AE11*$O11)+(AE11*$P11)+(AE11*$Q11)+($R11)+(AE11*((52+$S11)/52))*(1+$T11))*1/$L11 -> 158165.39 | AI11: =(AF11+(AF11*$J11)+(AF11*$M11)+(AF11*$N11)+(AF11*$O11)+(AF11*$P11)+(AF11*$Q11)+($R11)+(AF11*((52+$S11)/52))*(1+$T11))*1/$L11 -> 248348.2 | AJ11: =(AG11+(AG11*$J11)+(AG11*$M11)+(AG11*$N11)+(AG11*$O11)+(AG11*$P11)+(AG11*$Q11)+($R11)+(AG11*((52+$S11)/52))*(1+$T11))*1/$L11 -> 338531.01 | AK11: =AH11/52/$K11 -> 81.110455 | AL11: =AI11/52/$K11 -> 127.35805 | AM11: =AJ11/52/$K11 -> 173.60565 | AN11: =($V11*(1+(($U11/100)*2))) -> 66405.916 | AO11: =($W11*(1+(($U11/100)*2))) -> 104269.27 | AP11: =($X11*(1+(($U11/100)*2))) -> 142132.63 | AQ11: =(AN11+(AN11*$J11)+(AN11*$M11)+(AN11*$N11)+(AN11*$O11)+(AN11*$P11)+(AN11*$Q11)+($R11)+(AN11*((52+$S11)/52))*(1+$T11))*1/$L11 -> 158189.11 | AR11: =(AO11+(AO11*$J11)+(AO11*$M11)+(AO11*$N11)+(AO11*$O11)+(AO11*$P11)+(AO11*$Q11)+($R11)+(AO11*((52+$S11)/52))*(1+$T11))*1/$L11 -> 248385.45 | AS11: =(AP11+(AP11*$J11)+(AP11*$M11)+(AP11*$N11)+(AP11*$O11)+(AP11*$P11)+(AP11*$Q11)+($R11)+(AP11*((52+$S11)/52))*(1+$T11))*1/$L11 -> 338581.78 | AT11: =AQ11/52/$K11 -> 81.122619 | AU11: =AR11/52/$K11 -> 127.37715 | AV11: =AS11/52/$K11 -> 173.63168 | AW11: =($V11*(1+(($U11/100)*3))) -> 66415.874 | AX11: =($W11*(1+(($U11/100)*3))) -> 104284.91 | AY11: =($X11*(1+(($U11/100)*3))) -> 142153.94 | AZ11: =(AW11+(AW11*$J11)+(AW11*$M11)+(AW11*$N11)+(AW11*$O11)+(AW11*$P11)+(AW11*$Q11)+($R11)+(AW11*((52+$S11)/52))*(1+$T11))*1/$L11 -> 158212.83 | BA11: =(AX11+(AX11*$J11)+(AX11*$M11)+(AX11*$N11)+(AX11*$O11)+(AX11*$P11)+(AX11*$Q11)+($R11)+(AX11*((52+$S11)/52))*(1+$T11))*1/$L11 -> 248422.69 | BB11: =(AY11+(AY11*$J11)+(AY11*$M11)+(AY11*$N11)+(AY11*$O11)+(AY11*$P11)+(AY11*$Q11)+($R11)+(AY11*((52+$S11)/52))*(1+$T11))*1/$L11 -> 338632.56 | BC11: =AZ11/52/$K11 -> 81.134784 | BD11: =BA11/52/$K11 -> 127.39625 | BE11: =BB11/52/$K11 -> 173.65772 | BF11: =($V11*(1+(($U11/100)*4))) -> 66425.832 | BG11: =($W11*(1+(($U11/100)*4))) -> 104300.54 | BH11: =($X11*(1+(($U11/100)*4))) -> 142175.25 | BI11: =(BF11+(BF11*$J11)+(BF11*$M11)+(BF11*$N11)+(BF11*$O11)+(BF11*$P11)+(BF11*$Q11)+($R11)+(BF11*((52+$S11)/52))*(1+$T11))*1/$L11 -> 158236.55 | BJ11: =(BG11+(BG11*$J11)+(BG11*$M11)+(BG11*$N11)+(BG11*$O11)+(BG11*$P11)+(BG11*$Q11)+($R11)+(BG11*((52+$S11)/52))*(1+$T11))*1/$L11 -> 248459.94 | BK11: =(BH11+(BH11*$J11)+(BH11*$M11)+(BH11*$N11)+(BH11*$O11)+(BH11*$P11)+(BH11*$Q11)+($R11)+(BH11*((52+$S11)/52))*(1+$T11))*1/$L11 -> 338683.33 | BL11: =BI11/52/$K11 -> 81.146949 | BM11: =BJ11/52/$K11 -> 127.41535 | BN11: =BK11/52/$K11 -> 173.68376
A12: SA | B12: Admin staff | C12: AS | D12: S.A. PUBLIC SECTOR SALARIED EMPLOYEES INTERIM AWARD | E12: ASO2-1 - ASO3-3 | I12: 2022 | J12: 0.105 | K12: 37.5 | L12: 1 | M12: 0.1 | N12: 0.035 | O12: 0 | P12: 0 | Q12: 0.046 | R12: 0 | S12: 4 | T12: 0 | U12: 0.015 | V12: 56916 | W12: =V12+((X12-V12)/2) -> 63374 | X12: 69832 | Y12: =(V12+(V12*$J12)+(V12*$M12)+(V12*$N12)+(V12*$O12)+(V12*$P12)+(V12*$Q12)+($R12)+(V12*((52+$S12)/52))*(1+$T12))*1/$L12 -> 134488.13 | Z12: =(W12+(W12*$J12)+(W12*$M12)+(W12*$N12)+(W12*$O12)+(W12*$P12)+(W12*$Q12)+($R12)+(W12*((52+$S12)/52))*(1+$T12))*1/$L12 -> 149747.89 | AA12: =(X12+(X12*$J12)+(X12*$M12)+(X12*$N12)+(X12*$O12)+(X12*$P12)+(X12*$Q12)+($R12)+(X12*((52+$S12)/52))*(1+$T12))*1/$L12 -> 165007.64 | AB12: =Y12/52/$K12 -> 68.968272 | AC12: =Z12/52/$K12 -> 76.793788 | AD12: =AA12/52/$K12 -> 84.619305 | AE12: =($V12*(1+(($U12/100)*1))) -> 56924.537 | AF12: =($W12*(1+(($U12/100)*1))) -> 63383.506 | AG12: =($X12*(1+(($U12/100)*1))) -> 69842.475 | AH12: =(AE12+(AE12*$J12)+(AE12*$M12)+(AE12*$N12)+(AE12*$O12)+(AE12*$P12)+(AE12*$Q12)+($R12)+(AE12*((52+$S12)/52))*(1+$T12))*1/$L12 -> 134508.3 | AI12: =(AF12+(AF12*$J12)+(AF12*$M12)+(AF12*$N12)+(AF12*$O12)+(AF12*$P12)+(AF12*$Q12)+($R12)+(AF12*((52+$S12)/52))*(1+$T12))*1/$L12 -> 149770.35 | AJ12: =(AG12+(AG12*$J12)+(AG12*$M12)+(AG12*$N12)+(AG12*$O12)+(AG12*$P12)+(AG12*$Q12)+($R12)+(AG12*((52+$S12)/52))*(1+$T12))*1/$L12 -> 165032.4 | AK12: =AH12/52/$K12 -> 68.978617 | AL12: =AI12/52/$K12 -> 76.805307 | AM12: =AJ12/52/$K12 -> 84.631998 | AN12: =($V12*(1+(($U12/100)*2))) -> 56933.075 | AO12: =($W12*(1+(($U12/100)*2))) -> 63393.012 | AP12: =($X12*(1+(($U12/100)*2))) -> 69852.95 | AQ12: =(AN12+(AN12*$J12)+(AN12*$M12)+(AN12*$N12)+(AN12*$O12)+(AN12*$P12)+(AN12*$Q12)+($R12)+(AN12*((52+$S12)/52))*(1+$T12))*1/$L12 -> 134528.48 | AR12: =(AO12+(AO12*$J12)+(AO12*$M12)+(AO12*$N12)+(AO12*$O12)+(AO12*$P12)+(AO12*$Q12)+($R12)+(AO12*((52+$S12)/52))*(1+$T12))*1/$L12 -> 149792.81 | AS12: =(AP12+(AP12*$J12)+(AP12*$M12)+(AP12*$N12)+(AP12*$O12)+(AP12*$P12)+(AP12*$Q12)+($R12)+(AP12*((52+$S12)/52))*(1+$T12))*1/$L12 -> 165057.15 | AT12: =AQ12/52/$K12 -> 68.988962 | AU12: =AR12/52/$K12 -> 76.816826 | AV12: =AS12/52/$K12 -> 84.644691 | AW12: =($V12*(1+(($U12/100)*3))) -> 56941.612 | AX12: =($W12*(1+(($U12/100)*3))) -> 63402.518 | AY12: =($X12*(1+(($U12/100)*3))) -> 69863.424 | AZ12: =(AW12+(AW12*$J12)+(AW12*$M12)+(AW12*$N12)+(AW12*$O12)+(AW12*$P12)+(AW12*$Q12)+($R12)+(AW12*((52+$S12)/52))*(1+$T12))*1/$L12 -> 134548.65 | BA12: =(AX12+(AX12*$J12)+(AX12*$M12)+(AX12*$N12)+(AX12*$O12)+(AX12*$P12)+(AX12*$Q12)+($R12)+(AX12*((52+$S12)/52))*(1+$T12))*1/$L12 -> 149815.27 | BB12: =(AY12+(AY12*$J12)+(AY12*$M12)+(AY12*$N12)+(AY12*$O12)+(AY12*$P12)+(AY12*$Q12)+($R12)+(AY12*((52+$S12)/52))*(1+$T12))*1/$L12 -> 165081.9 | BC12: =AZ12/52/$K12 -> 68.999307 | BD12: =BA12/52/$K12 -> 76.828345 | BE12: =BB12/52/$K12 -> 84.657383 | BF12: =($V12*(1+(($U12/100)*4))) -> 56950.15 | BG12: =($W12*(1+(($U12/100)*4))) -> 63412.024 | BH12: =($X12*(1+(($U12/100)*4))) -> 69873.899 | BI12: =(BF12+(BF12*$J12)+(BF12*$M12)+(BF12*$N12)+(BF12*$O12)+(BF12*$P12)+(BF12*$Q12)+($R12)+(BF12*((52+$S12)/52))*(1+$T12))*1/$L12 -> 134568.82 | BJ12: =(BG12+(BG12*$J12)+(BG12*$M12)+(BG12*$N12)+(BG12*$O12)+(BG12*$P12)+(BG12*$Q12)+($R12)+(BG12*((52+$S12)/52))*(1+$T12))*1/$L12 -> 149837.74 | BK12: =(BH12+(BH12*$J12)+(BH12*$M12)+(BH12*$N12)+(BH12*$O12)+(BH12*$P12)+(BH12*$Q12)+($R12)+(BH12*((52+$S12)/52))*(1+$T12))*1/$L12 -> 165106.65 | BL12: =BI12/52/$K12 -> 69.009653 | BM12: =BJ12/52/$K12 -> 76.839865 | BN12: =BK12/52/$K12 -> 84.670076
A13: SA | B13: Bioinformatics staff | C13: BI | D13: S.A. PUBLIC SECTOR SALARIED EMPLOYEES INTERIM AWARD | E13: PO-1 - PO-4 | I13: 2022 | J13: 0.105 | K13: 37.5 | L13: 1 | M13: 0.1 | N13: 0.035 | O13: 0 | P13: 0 | Q13: 0.046 | R13: 0 | S13: 4 | T13: 0 | U13: 0.015 | V13: 66386 | W13: =V13+((X13-V13)/2) -> 91587.5 | X13: 116789 | Y13: =(V13+(V13*$J13)+(V13*$M13)+(V13*$N13)+(V13*$O13)+(V13*$P13)+(V13*$Q13)+($R13)+(V13*((52+$S13)/52))*(1+$T13))*1/$L13 -> 156865.01 | Z13: =(W13+(W13*$J13)+(W13*$M13)+(W13*$N13)+(W13*$O13)+(W13*$P13)+(W13*$Q13)+($R13)+(W13*((52+$S13)/52))*(1+$T13))*1/$L13 -> 216414.22 | AA13: =(X13+(X13*$J13)+(X13*$M13)+(X13*$N13)+(X13*$O13)+(X13*$P13)+(X13*$Q13)+($R13)+(X13*((52+$S13)/52))*(1+$T13))*1/$L13 -> 275963.42 | AB13: =Y13/52/$K13 -> 80.443596 | AC13: =Z13/52/$K13 -> 110.98165 | AD13: =AA13/52/$K13 -> 141.5197 | AE13: =($V13*(1+(($U13/100)*1))) -> 66395.958 | AF13: =($W13*(1+(($U13/100)*1))) -> 91601.238 | AG13: =($X13*(1+(($U13/100)*1))) -> 116806.52 | AH13: =(AE13+(AE13*$J13)+(AE13*$M13)+(AE13*$N13)+(AE13*$O13)+(AE13*$P13)+(AE13*$Q13)+($R13)+(AE13*((52+$S13)/52))*(1+$T13))*1/$L13 -> 156888.54 | AI13: =(AF13+(AF13*$J13)+(AF13*$M13)+(AF13*$N13)+(AF13*$O13)+(AF13*$P13)+(AF13*$Q13)+($R13)+(AF13*((52+$S13)/52))*(1+$T13))*1/$L13 -> 216446.68 | AJ13: =(AG13+(AG13*$J13)+(AG13*$M13)+(AG13*$N13)+(AG13*$O13)+(AG13*$P13)+(AG13*$Q13)+($R13)+(AG13*((52+$S13)/52))*(1+$T13))*1/$L13 -> 276004.82 | AK13: =AH13/52/$K13 -> 80.455662 | AL13: =AI13/52/$K13 -> 110.9983 | AM13: =AJ13/52/$K13 -> 141.54093 | AN13: =($V13*(1+(($U13/100)*2))) -> 66405.916 | AO13: =($W13*(1+(($U13/100)*2))) -> 91614.976 | AP13: =($X13*(1+(($U13/100)*2))) -> 116824.04 | AQ13: =(AN13+(AN13*$J13)+(AN13*$M13)+(AN13*$N13)+(AN13*$O13)+(AN13*$P13)+(AN13*$Q13)+($R13)+(AN13*((52+$S13)/52))*(1+$T13))*1/$L13 -> 156912.07 | AR13: =(AO13+(AO13*$J13)+(AO13*$M13)+(AO13*$N13)+(AO13*$O13)+(AO13*$P13)+(AO13*$Q13)+($R13)+(AO13*((52+$S13)/52))*(1+$T13))*1/$L13 -> 216479.14 | AS13: =(AP13+(AP13*$J13)+(AP13*$M13)+(AP13*$N13)+(AP13*$O13)+(AP13*$P13)+(AP13*$Q13)+($R13)+(AP13*((52+$S13)/52))*(1+$T13))*1/$L13 -> 276046.21 | AT13: =AQ13/52/$K13 -> 80.467729 | AU13: =AR13/52/$K13 -> 111.01494 | AV13: =AS13/52/$K13 -> 141.56216 | AW13: =($V13*(1+(($U13/100)*3))) -> 66415.874 | AX13: =($W13*(1+(($U13/100)*3))) -> 91628.714 | AY13: =($X13*(1+(($U13/100)*3))) -> 116841.56 | AZ13: =(AW13+(AW13*$J13)+(AW13*$M13)+(AW13*$N13)+(AW13*$O13)+(AW13*$P13)+(AW13*$Q13)+($R13)+(AW13*((52+$S13)/52))*(1+$T13))*1/$L13 -> 156935.6 | BA13: =(AX13+(AX13*$J13)+(AX13*$M13)+(AX13*$N13)+(AX13*$O13)+(AX13*$P13)+(AX13*$Q13)+($R13)+(AX13*((52+$S13)/52))*(1+$T13))*1/$L13 -> 216511.6 | BB13: =(AY13+(AY13*$J13)+(AY13*$M13)+(AY13*$N13)+(AY13*$O13)+(AY13*$P13)+(AY13*$Q13)+($R13)+(AY13*((52+$S13)/52))*(1+$T13))*1/$L13 -> 276087.61 | BC13: =AZ13/52/$K13 -> 80.479795 | BD13: =BA13/52/$K13 -> 111.03159 | BE13: =BB13/52/$K13 -> 141.58339 | BF13: =($V13*(1+(($U13/100)*4))) -> 66425.832 | BG13: =($W13*(1+(($U13/100)*4))) -> 91642.452 | BH13: =($X13*(1+(($U13/100)*4))) -> 116859.07 | BI13: =(BF13+(BF13*$J13)+(BF13*$M13)+(BF13*$N13)+(BF13*$O13)+(BF13*$P13)+(BF13*$Q13)+($R13)+(BF13*((52+$S13)/52))*(1+$T13))*1/$L13 -> 156959.13 | BJ13: =(BG13+(BG13*$J13)+(BG13*$M13)+(BG13*$N13)+(BG13*$O13)+(BG13*$P13)+(BG13*$Q13)+($R13)+(BG13*((52+$S13)/52))*(1+$T13))*1/$L13 -> 216544.07 | BK13: =(BH13+(BH13*$J13)+(BH13*$M13)+(BH13*$N13)+(BH13*$O13)+(BH13*$P13)+(BH13*$Q13)+($R13)+(BH13*((52+$S13)/52))*(1+$T13))*1/$L13 -> 276129 | BL13: =BI13/52/$K13 -> 80.491862 | BM13: =BJ13/52/$K13 -> 111.04824 | BN13: =BK13/52/$K13 -> 141.60462
A14: SA | B14: Pathologists | C14: MP | D14: SA Health Salaried Medical Officers Enterprise Agreement 2022 | E14: MD0201 - MD029G | I14: 2022 | J14: 0.105 | K14: 38 | L14: 1 | M14: 0 | N14: 0.035 | O14: 0 | P14: 0.6 | Q14: 0.046 | R14: 26000 | S14: 5 | T14: 0.175 | U14: 0.015 | V14: 221622 | W14: =V14+((X14-V14)/2) -> 256820.5 | X14: 292019 | Y14: =(V14+(V14*$J14)+(V14*$M14)+(V14*$N14)+(V14*$O14)+(V14*$P14)+(V14*$Q14)+($R14)+(V14*((52+$S14)/52))*(1+$T14))*1/$L14 -> 707261.77 | Z14: =(W14+(W14*$J14)+(W14*$M14)+(W14*$N14)+(W14*$O14)+(W14*$P14)+(W14*$Q14)+($R14)+(W14*((52+$S14)/52))*(1+$T14))*1/$L14 -> 815461.28 | AA14: =(X14+(X14*$J14)+(X14*$M14)+(X14*$N14)+(X14*$O14)+(X14*$P14)+(X14*$Q14)+($R14)+(X14*((52+$S14)/52))*(1+$T14))*1/$L14 -> 923660.79 | AB14: =Y14/52/$K14 -> 357.92599 | AC14: =Z14/52/$K14 -> 412.68283 | AD14: =AA14/52/$K14 -> 467.43967 | AE14: =($V14*(1+(($U14/100)*1))) -> 221655.24 | AF14: =($W14*(1+(($U14/100)*1))) -> 256859.02 | AG14: =($X14*(1+(($U14/100)*1))) -> 292062.8 | AH14: =(AE14+(AE14*$J14)+(AE14*$M14)+(AE14*$N14)+(AE14*$O14)+(AE14*$P14)+(AE14*$Q14)+($R14)+(AE14*((52+$S14)/52))*(1+$T14))*1/$L14 -> 707363.96 | AI14: =(AF14+(AF14*$J14)+(AF14*$M14)+(AF14*$N14)+(AF14*$O14)+(AF14*$P14)+(AF14*$Q14)+($R14)+(AF14*((52+$S14)/52))*(1+$T14))*1/$L14 -> 815579.7 | AJ14: =(AG14+(AG14*$J14)+(AG14*$M14)+(AG14*$N14)+(AG14*$O14)+(AG14*$P14)+(AG14*$Q14)+($R14)+(AG14*((52+$S14)/52))*(1+$T14))*1/$L14 -> 923795.44 | AK14: =AH14/52/$K14 -> 357.97771 | AL14: =AI14/52/$K14 -> 412.74276 | AM14: =AJ14/52/$K14 -> 467.50781 | AN14: =($V14*(1+(($U14/100)*2))) -> 221688.49 | AO14: =($W14*(1+(($U14/100)*2))) -> 256897.55 | AP14: =($X14*(1+(($U14/100)*2))) -> 292106.61 | AQ14: =(AN14+(AN14*$J14)+(AN14*$M14)+(AN14*$N14)+(AN14*$O14)+(AN14*$P14)+(AN14*$Q14)+($R14)+(AN14*((52+$S14)/52))*(1+$T14))*1/$L14 -> 707466.14 | AR14: =(AO14+(AO14*$J14)+(AO14*$M14)+(AO14*$N14)+(AO14*$O14)+(AO14*$P14)+(AO14*$Q14)+($R14)+(AO14*((52+$S14)/52))*(1+$T14))*1/$L14 -> 815698.12 | AS14: =(AP14+(AP14*$J14)+(AP14*$M14)+(AP14*$N14)+(AP14*$O14)+(AP14*$P14)+(AP14*$Q14)+($R14)+(AP14*((52+$S14)/52))*(1+$T14))*1/$L14 -> 923930.09 | AT14: =AQ14/52/$K14 -> 358.02943 | AU14: =AR14/52/$K14 -> 412.80269 | AV14: =AS14/52/$K14 -> 467.57596 | AW14: =($V14*(1+(($U14/100)*3))) -> 221721.73 | AX14: =($W14*(1+(($U14/100)*3))) -> 256936.07 | AY14: =($X14*(1+(($U14/100)*3))) -> 292150.41 | AZ14: =(AW14+(AW14*$J14)+(AW14*$M14)+(AW14*$N14)+(AW14*$O14)+(AW14*$P14)+(AW14*$Q14)+($R14)+(AW14*((52+$S14)/52))*(1+$T14))*1/$L14 -> 707568.33 | BA14: =(AX14+(AX14*$J14)+(AX14*$M14)+(AX14*$N14)+(AX14*$O14)+(AX14*$P14)+(AX14*$Q14)+($R14)+(AX14*((52+$S14)/52))*(1+$T14))*1/$L14 -> 815816.54 | BB14: =(AY14+(AY14*$J14)+(AY14*$M14)+(AY14*$N14)+(AY14*$O14)+(AY14*$P14)+(AY14*$Q14)+($R14)+(AY14*((52+$S14)/52))*(1+$T14))*1/$L14 -> 924064.74 | BC14: =AZ14/52/$K14 -> 358.08114 | BD14: =BA14/52/$K14 -> 412.86262 | BE14: =BB14/52/$K14 -> 467.6441 | BF14: =($V14*(1+(($U14/100)*4))) -> 221754.97 | BG14: =($W14*(1+(($U14/100)*4))) -> 256974.59 | BH14: =($X14*(1+(($U14/100)*4))) -> 292194.21 | BI14: =(BF14+(BF14*$J14)+(BF14*$M14)+(BF14*$N14)+(BF14*$O14)+(BF14*$P14)+(BF14*$Q14)+($R14)+(BF14*((52+$S14)/52))*(1+$T14))*1/$L14 -> 707670.52 | BJ14: =(BG14+(BG14*$J14)+(BG14*$M14)+(BG14*$N14)+(BG14*$O14)+(BG14*$P14)+(BG14*$Q14)+($R14)+(BG14*((52+$S14)/52))*(1+$T14))*1/$L14 -> 815934.95 | BK14: =(BH14+(BH14*$J14)+(BH14*$M14)+(BH14*$N14)+(BH14*$O14)+(BH14*$P14)+(BH14*$Q14)+($R14)+(BH14*((52+$S14)/52))*(1+$T14))*1/$L14 -> 924199.39 | BL14: =BI14/52/$K14 -> 358.13286 | BM14: =BJ14/52/$K14 -> 412.92255 | BN14: =BK14/52/$K14 -> 467.71224
A16: NSW | B16: Lab technician | C16: LT | D16: Health Employees (State) Award | E16: Tech Assistant G1-3 | I16: 2022 | J16: 0.105 | K16: 40 | L16: 1 | M16: 0.1 | N16: 0.035 | O16: 0 | P16: 0 | Q16: 0.046 | R16: 0 | S16: 4 | T16: 0 | U16: 0.015 | V16: =1154.19*52 -> 60017.88 | W16: =V16+((X16-V16)/2) -> 77637.56 | X16: =1831.87*52 -> 95257.24 | Y16: =(V16+(V16*$J16)+(V16*$M16)+(V16*$N16)+(V16*$O16)+(V16*$P16)+(V16*$Q16)+($R16)+(V16*((52+$S16)/52))*(1+$T16))*1/$L16 -> 141817.63 | Z16: =(W16+(W16*$J16)+(W16*$M16)+(W16*$N16)+(W16*$O16)+(W16*$P16)+(W16*$Q16)+($R16)+(W16*((52+$S16)/52))*(1+$T16))*1/$L16 -> 183451.58 | AA16: =(X16+(X16*$J16)+(X16*$M16)+(X16*$N16)+(X16*$O16)+(X16*$P16)+(X16*$Q16)+($R16)+(X16*((52+$S16)/52))*(1+$T16))*1/$L16 -> 225085.53 | AB16: =Y16/52/$K16 -> 68.181555 | AC16: =Z16/52/$K16 -> 88.197876 | AD16: =AA16/52/$K16 -> 108.2142 | AE16: =($V16*(1+(($U16/100)*1))) -> 60026.883 | AF16: =($W16*(1+(($U16/100)*1))) -> 77649.206 | AG16: =($X16*(1+(($U16/100)*1))) -> 95271.529 | AH16: =(AE16+(AE16*$J16)+(AE16*$M16)+(AE16*$N16)+(AE16*$O16)+(AE16*$P16)+(AE16*$Q16)+($R16)+(AE16*((52+$S16)/52))*(1+$T16))*1/$L16 -> 141838.91 | AI16: =(AF16+(AF16*$J16)+(AF16*$M16)+(AF16*$N16)+(AF16*$O16)+(AF16*$P16)+(AF16*$Q16)+($R16)+(AF16*((52+$S16)/52))*(1+$T16))*1/$L16 -> 183479.1 | AJ16: =(AG16+(AG16*$J16)+(AG16*$M16)+(AG16*$N16)+(AG16*$O16)+(AG16*$P16)+(AG16*$Q16)+($R16)+(AG16*((52+$S16)/52))*(1+$T16))*1/$L16 -> 225119.29 | AK16: =AH16/52/$K16 -> 68.191782 | AL16: =AI16/52/$K16 -> 88.211106 | AM16: =AJ16/52/$K16 -> 108.23043 | AN16: =($V16*(1+(($U16/100)*2))) -> 60035.885 | AO16: =($W16*(1+(($U16/100)*2))) -> 77660.851 | AP16: =($X16*(1+(($U16/100)*2))) -> 95285.817 | AQ16: =(AN16+(AN16*$J16)+(AN16*$M16)+(AN16*$N16)+(AN16*$O16)+(AN16*$P16)+(AN16*$Q16)+($R16)+(AN16*((52+$S16)/52))*(1+$T16))*1/$L16 -> 141860.18 | AR16: =(AO16+(AO16*$J16)+(AO16*$M16)+(AO16*$N16)+(AO16*$O16)+(AO16*$P16)+(AO16*$Q16)+($R16)+(AO16*((52+$S16)/52))*(1+$T16))*1/$L16 -> 183506.62 | AS16: =(AP16+(AP16*$J16)+(AP16*$M16)+(AP16*$N16)+(AP16*$O16)+(AP16*$P16)+(AP16*$Q16)+($R16)+(AP16*((52+$S16)/52))*(1+$T16))*1/$L16 -> 225153.06 | AT16: =AQ16/52/$K16 -> 68.202009 | AU16: =AR16/52/$K16 -> 88.224335 | AV16: =AS16/52/$K16 -> 108.24666 | AW16: =($V16*(1+(($U16/100)*3))) -> 60044.888 | AX16: =($W16*(1+(($U16/100)*3))) -> 77672.497 | AY16: =($X16*(1+(($U16/100)*3))) -> 95300.106 | AZ16: =(AW16+(AW16*$J16)+(AW16*$M16)+(AW16*$N16)+(AW16*$O16)+(AW16*$P16)+(AW16*$Q16)+($R16)+(AW16*((52+$S16)/52))*(1+$T16))*1/$L16 -> 141881.45 | BA16: =(AX16+(AX16*$J16)+(AX16*$M16)+(AX16*$N16)+(AX16*$O16)+(AX16*$P16)+(AX16*$Q16)+($R16)+(AX16*((52+$S16)/52))*(1+$T16))*1/$L16 -> 183534.14 | BB16: =(AY16+(AY16*$J16)+(AY16*$M16)+(AY16*$N16)+(AY16*$O16)+(AY16*$P16)+(AY16*$Q16)+($R16)+(AY16*((52+$S16)/52))*(1+$T16))*1/$L16 -> 225186.82 | BC16: =AZ16/52/$K16 -> 68.212236 | BD16: =BA16/52/$K16 -> 88.237565 | BE16: =BB16/52/$K16 -> 108.26289 | BF16: =($V16*(1+(($U16/100)*4))) -> 60053.891 | BG16: =($W16*(1+(($U16/100)*4))) -> 77684.143 | BH16: =($X16*(1+(($U16/100)*4))) -> 95314.394 | BI16: =(BF16+(BF16*$J16)+(BF16*$M16)+(BF16*$N16)+(BF16*$O16)+(BF16*$P16)+(BF16*$Q16)+($R16)+(BF16*((52+$S16)/52))*(1+$T16))*1/$L16 -> 141902.72 | BJ16: =(BG16+(BG16*$J16)+(BG16*$M16)+(BG16*$N16)+(BG16*$O16)+(BG16*$P16)+(BG16*$Q16)+($R16)+(BG16*((52+$S16)/52))*(1+$T16))*1/$L16 -> 183561.65 | BK16: =(BH16+(BH16*$J16)+(BH16*$M16)+(BH16*$N16)+(BH16*$O16)+(BH16*$P16)+(BH16*$Q16)+($R16)+(BH16*((52+$S16)/52))*(1+$T16))*1/$L16 -> 225220.58 | BL16: =BI16/52/$K16 -> 68.222464 | BM16: =BJ16/52/$K16 -> 88.250795 | BN16: =BK16/52/$K16 -> 108.27913
A17: NSW | B17: Medical scientist | C17: MS | D17: Hospital Scientists (State) Award | E17: 1-3 | I17: 2022 | J17: 0.105 | K17: 38 | L17: 1 | M17: 0.1 | N17: 0.035 | O17: 0 | P17: 0 | Q17: 0.046 | R17: 0 | S17: 4 | T17: 0.175 | U17: 0.015 | V17: =1292.77*52 -> 67224.04 | W17: =V17+((X17-V17)/2) -> 102899.68 | X17: =2664.91*52 -> 138575.32 | Y17: =(V17+(V17*$J17)+(V17*$M17)+(V17*$N17)+(V17*$O17)+(V17*$P17)+(V17*$Q17)+($R17)+(V17*((52+$S17)/52))*(1+$T17))*1/$L17 -> 171514.38 | Z17: =(W17+(W17*$J17)+(W17*$M17)+(W17*$N17)+(W17*$O17)+(W17*$P17)+(W17*$Q17)+($R17)+(W17*((52+$S17)/52))*(1+$T17))*1/$L17 -> 262536.66 | AA17: =(X17+(X17*$J17)+(X17*$M17)+(X17*$N17)+(X17*$O17)+(X17*$P17)+(X17*$Q17)+($R17)+(X17*((52+$S17)/52))*(1+$T17))*1/$L17 -> 353558.94 | AB17: =Y17/52/$K17 -> 86.798776 | AC17: =Z17/52/$K17 -> 132.86268 | AD17: =AA17/52/$K17 -> 178.92659 | AE17: =($V17*(1+(($U17/100)*1))) -> 67234.124 | AF17: =($W17*(1+(($U17/100)*1))) -> 102915.11 | AG17: =($X17*(1+(($U17/100)*1))) -> 138596.11 | AH17: =(AE17+(AE17*$J17)+(AE17*$M17)+(AE17*$N17)+(AE17*$O17)+(AE17*$P17)+(AE17*$Q17)+($R17)+(AE17*((52+$S17)/52))*(1+$T17))*1/$L17 -> 171540.11 | AI17: =(AF17+(AF17*$J17)+(AF17*$M17)+(AF17*$N17)+(AF17*$O17)+(AF17*$P17)+(AF17*$Q17)+($R17)+(AF17*((52+$S17)/52))*(1+$T17))*1/$L17 -> 262576.04 | AJ17: =(AG17+(AG17*$J17)+(AG17*$M17)+(AG17*$N17)+(AG17*$O17)+(AG17*$P17)+(AG17*$Q17)+($R17)+(AG17*((52+$S17)/52))*(1+$T17))*1/$L17 -> 353611.97 | AK17: =AH17/52/$K17 -> 86.811796 | AL17: =AI17/52/$K17 -> 132.88261 | AM17: =AJ17/52/$K17 -> 178.95343 | AN17: =($V17*(1+(($U17/100)*2))) -> 67244.207 | AO17: =($W17*(1+(($U17/100)*2))) -> 102930.55 | AP17: =($X17*(1+(($U17/100)*2))) -> 138616.89 | AQ17: =(AN17+(AN17*$J17)+(AN17*$M17)+(AN17*$N17)+(AN17*$O17)+(AN17*$P17)+(AN17*$Q17)+($R17)+(AN17*((52+$S17)/52))*(1+$T17))*1/$L17 -> 171565.84 | AR17: =(AO17+(AO17*$J17)+(AO17*$M17)+(AO17*$N17)+(AO17*$O17)+(AO17*$P17)+(AO17*$Q17)+($R17)+(AO17*((52+$S17)/52))*(1+$T17))*1/$L17 -> 262615.42 | AS17: =(AP17+(AP17*$J17)+(AP17*$M17)+(AP17*$N17)+(AP17*$O17)+(AP17*$P17)+(AP17*$Q17)+($R17)+(AP17*((52+$S17)/52))*(1+$T17))*1/$L17 -> 353665.01 | AT17: =AQ17/52/$K17 -> 86.824816 | AU17: =AR17/52/$K17 -> 132.90254 | AV17: =AS17/52/$K17 -> 178.98027 | AW17: =($V17*(1+(($U17/100)*3))) -> 67254.291 | AX17: =($W17*(1+(($U17/100)*3))) -> 102945.98 | AY17: =($X17*(1+(($U17/100)*3))) -> 138637.68 | AZ17: =(AW17+(AW17*$J17)+(AW17*$M17)+(AW17*$N17)+(AW17*$O17)+(AW17*$P17)+(AW17*$Q17)+($R17)+(AW17*((52+$S17)/52))*(1+$T17))*1/$L17 -> 171591.56 | BA17: =(AX17+(AX17*$J17)+(AX17*$M17)+(AX17*$N17)+(AX17*$O17)+(AX17*$P17)+(AX17*$Q17)+($R17)+(AX17*((52+$S17)/52))*(1+$T17))*1/$L17 -> 262654.8 | BB17: =(AY17+(AY17*$J17)+(AY17*$M17)+(AY17*$N17)+(AY17*$O17)+(AY17*$P17)+(AY17*$Q17)+($R17)+(AY17*((52+$S17)/52))*(1+$T17))*1/$L17 -> 353718.04 | BC17: =AZ17/52/$K17 -> 86.837835 | BD17: =BA17/52/$K17 -> 132.92247 | BE17: =BB17/52/$K17 -> 179.00711 | BF17: =($V17*(1+(($U17/100)*4))) -> 67264.374 | BG17: =($W17*(1+(($U17/100)*4))) -> 102961.42 | BH17: =($X17*(1+(($U17/100)*4))) -> 138658.47 | BI17: =(BF17+(BF17*$J17)+(BF17*$M17)+(BF17*$N17)+(BF17*$O17)+(BF17*$P17)+(BF17*$Q17)+($R17)+(BF17*((52+$S17)/52))*(1+$T17))*1/$L17 -> 171617.29 | BJ17: =(BG17+(BG17*$J17)+(BG17*$M17)+(BG17*$N17)+(BG17*$O17)+(BG17*$P17)+(BG17*$Q17)+($R17)+(BG17*((52+$S17)/52))*(1+$T17))*1/$L17 -> 262694.18 | BK17: =(BH17+(BH17*$J17)+(BH17*$M17)+(BH17*$N17)+(BH17*$O17)+(BH17*$P17)+(BH17*$Q17)+($R17)+(BH17*((52+$S17)/52))*(1+$T17))*1/$L17 -> 353771.07 | BL17: =BI17/52/$K17 -> 86.850855 | BM17: =BJ17/52/$K17 -> 132.9424 | BN17: =BK17/52/$K17 -> 179.03394
A18: NSW | B18: Admin staff | C18: AS | I18: 2022 | J18: 0.105 | K18: 40 | L18: 1 | M18: 0.1 | N18: 0.035 | O18: 0 | P18: 0 | Q18: 0.046 | R18: 0 | S18: 4 | T18: 0 | U18: 0.015 | V18: =926.56*52 -> 48181.12 | W18: =V18+((X18-V18)/2) -> 57943.08 | X18: =1302.02*52 -> 67705.04 | Y18: =(V18+(V18*$J18)+(V18*$M18)+(V18*$N18)+(V18*$O18)+(V18*$P18)+(V18*$Q18)+($R18)+(V18*((52+$S18)/52))*(1+$T18))*1/$L18 -> 113848.28 | Z18: =(W18+(W18*$J18)+(W18*$M18)+(W18*$N18)+(W18*$O18)+(W18*$P18)+(W18*$Q18)+($R18)+(W18*((52+$S18)/52))*(1+$T18))*1/$L18 -> 136915.04 | AA18: =(X18+(X18*$J18)+(X18*$M18)+(X18*$N18)+(X18*$O18)+(X18*$P18)+(X18*$Q18)+($R18)+(X18*((52+$S18)/52))*(1+$T18))*1/$L18 -> 159981.8 | AB18: =Y18/52/$K18 -> 54.73475 | AC18: =Z18/52/$K18 -> 65.824539 | AD18: =AA18/52/$K18 -> 76.914328 | AE18: =($V18*(1+(($U18/100)*1))) -> 48188.347 | AF18: =($W18*(1+(($U18/100)*1))) -> 57951.771 | AG18: =($X18*(1+(($U18/100)*1))) -> 67715.196 | AH18: =(AE18+(AE18*$J18)+(AE18*$M18)+(AE18*$N18)+(AE18*$O18)+(AE18*$P18)+(AE18*$Q18)+($R18)+(AE18*((52+$S18)/52))*(1+$T18))*1/$L18 -> 113865.36 | AI18: =(AF18+(AF18*$J18)+(AF18*$M18)+(AF18*$N18)+(AF18*$O18)+(AF18*$P18)+(AF18*$Q18)+($R18)+(AF18*((52+$S18)/52))*(1+$T18))*1/$L18 -> 136935.58 | AJ18: =(AG18+(AG18*$J18)+(AG18*$M18)+(AG18*$N18)+(AG18*$O18)+(AG18*$P18)+(AG18*$Q18)+($R18)+(AG18*((52+$S18)/52))*(1+$T18))*1/$L18 -> 160005.8 | AK18: =AH18/52/$K18 -> 54.74296 | AL18: =AI18/52/$K18 -> 65.834413 | AM18: =AJ18/52/$K18 -> 76.925865 | AN18: =($V18*(1+(($U18/100)*2))) -> 48195.574 | AO18: =($W18*(1+(($U18/100)*2))) -> 57960.463 | AP18: =($X18*(1+(($U18/100)*2))) -> 67725.352 | AQ18: =(AN18+(AN18*$J18)+(AN18*$M18)+(AN18*$N18)+(AN18*$O18)+(AN18*$P18)+(AN18*$Q18)+($R18)+(AN18*((52+$S18)/52))*(1+$T18))*1/$L18 -> 113882.43 | AR18: =(AO18+(AO18*$J18)+(AO18*$M18)+(AO18*$N18)+(AO18*$O18)+(AO18*$P18)+(AO18*$Q18)+($R18)+(AO18*((52+$S18)/52))*(1+$T18))*1/$L18 -> 136956.12 | AS18: =(AP18+(AP18*$J18)+(AP18*$M18)+(AP18*$N18)+(AP18*$O18)+(AP18*$P18)+(AP18*$Q18)+($R18)+(AP18*((52+$S18)/52))*(1+$T18))*1/$L18 -> 160029.8 | AT18: =AQ18/52/$K18 -> 54.751171 | AU18: =AR18/52/$K18 -> 65.844286 | AV18: =AS18/52/$K18 -> 76.937402 | AW18: =($V18*(1+(($U18/100)*3))) -> 48202.802 | AX18: =($W18*(1+(($U18/100)*3))) -> 57969.154 | AY18: =($X18*(1+(($U18/100)*3))) -> 67735.507 | AZ18: =(AW18+(AW18*$J18)+(AW18*$M18)+(AW18*$N18)+(AW18*$O18)+(AW18*$P18)+(AW18*$Q18)+($R18)+(AW18*((52+$S18)/52))*(1+$T18))*1/$L18 -> 113899.51 | BA18: =(AX18+(AX18*$J18)+(AX18*$M18)+(AX18*$N18)+(AX18*$O18)+(AX18*$P18)+(AX18*$Q18)+($R18)+(AX18*((52+$S18)/52))*(1+$T18))*1/$L18 -> 136976.65 | BB18: =(AY18+(AY18*$J18)+(AY18*$M18)+(AY18*$N18)+(AY18*$O18)+(AY18*$P18)+(AY18*$Q18)+($R18)+(AY18*((52+$S18)/52))*(1+$T18))*1/$L18 -> 160053.79 | BC18: =AZ18/52/$K18 -> 54.759381 | BD18: =BA18/52/$K18 -> 65.85416 | BE18: =BB18/52/$K18 -> 76.948939 | BF18: =($V18*(1+(($U18/100)*4))) -> 48210.029 | BG18: =($W18*(1+(($U18/100)*4))) -> 57977.846 | BH18: =($X18*(1+(($U18/100)*4))) -> 67745.663 | BI18: =(BF18+(BF18*$J18)+(BF18*$M18)+(BF18*$N18)+(BF18*$O18)+(BF18*$P18)+(BF18*$Q18)+($R18)+(BF18*((52+$S18)/52))*(1+$T18))*1/$L18 -> 113916.59 | BJ18: =(BG18+(BG18*$J18)+(BG18*$M18)+(BG18*$N18)+(BG18*$O18)+(BG18*$P18)+(BG18*$Q18)+($R18)+(BG18*((52+$S18)/52))*(1+$T18))*1/$L18 -> 136997.19 | BK18: =(BH18+(BH18*$J18)+(BH18*$M18)+(BH18*$N18)+(BH18*$O18)+(BH18*$P18)+(BH18*$Q18)+($R18)+(BH18*((52+$S18)/52))*(1+$T18))*1/$L18 -> 160077.79 | BL18: =BI18/52/$K18 -> 54.767591 | BM18: =BJ18/52/$K18 -> 65.864034 | BN18: =BK18/52/$K18 -> 76.960476
A19: NSW | B19: Bioinformatics staff | C19: BI | D19: Hospital Scientists (State) Award | E19: 1-3 | I19: 2022 | J19: 0.105 | K19: 40 | L19: 1 | M19: 0.1 | N19: 0.035 | O19: 0 | P19: 0 | Q19: 0.046 | R19: 0 | S19: 4 | T19: 0.175 | U19: 0.015 | V19: 66106 | W19: =V19+((X19-V19)/2) -> 90434.5 | X19: 114763 | Y19: =(V19+(V19*$J19)+(V19*$M19)+(V19*$N19)+(V19*$O19)+(V19*$P19)+(V19*$Q19)+($R19)+(V19*((52+$S19)/52))*(1+$T19))*1/$L19 -> 168661.83 | Z19: =(W19+(W19*$J19)+(W19*$M19)+(W19*$N19)+(W19*$O19)+(W19*$P19)+(W19*$Q19)+($R19)+(W19*((52+$S19)/52))*(1+$T19))*1/$L19 -> 230733.19 | AA19: =(X19+(X19*$J19)+(X19*$M19)+(X19*$N19)+(X19*$O19)+(X19*$P19)+(X19*$Q19)+($R19)+(X19*((52+$S19)/52))*(1+$T19))*1/$L19 -> 292804.55 | AB19: =Y19/52/$K19 -> 81.087419 | AC19: =Z19/52/$K19 -> 110.92942 | AD19: =AA19/52/$K19 -> 140.77142 | AE19: =($V19*(1+(($U19/100)*1))) -> 66115.916 | AF19: =($W19*(1+(($U19/100)*1))) -> 90448.065 | AG19: =($X19*(1+(($U19/100)*1))) -> 114780.21 | AH19: =(AE19+(AE19*$J19)+(AE19*$M19)+(AE19*$N19)+(AE19*$O19)+(AE19*$P19)+(AE19*$Q19)+($R19)+(AE19*((52+$S19)/52))*(1+$T19))*1/$L19 -> 168687.13 | AI19: =(AF19+(AF19*$J19)+(AF19*$M19)+(AF19*$N19)+(AF19*$O19)+(AF19*$P19)+(AF19*$Q19)+($R19)+(AF19*((52+$S19)/52))*(1+$T19))*1/$L19 -> 230767.8 | AJ19: =(AG19+(AG19*$J19)+(AG19*$M19)+(AG19*$N19)+(AG19*$O19)+(AG19*$P19)+(AG19*$Q19)+($R19)+(AG19*((52+$S19)/52))*(1+$T19))*1/$L19 -> 292848.47 | AK19: =AH19/52/$K19 -> 81.099582 | AL19: =AI19/52/$K19 -> 110.94606 | AM19: =AJ19/52/$K19 -> 140.79254 | AN19: =($V19*(1+(($U19/100)*2))) -> 66125.832 | AO19: =($W19*(1+(($U19/100)*2))) -> 90461.63 | AP19: =($X19*(1+(($U19/100)*2))) -> 114797.43 | AQ19: =(AN19+(AN19*$J19)+(AN19*$M19)+(AN19*$N19)+(AN19*$O19)+(AN19*$P19)+(AN19*$Q19)+($R19)+(AN19*((52+$S19)/52))*(1+$T19))*1/$L19 -> 168712.43 | AR19: =(AO19+(AO19*$J19)+(AO19*$M19)+(AO19*$N19)+(AO19*$O19)+(AO19*$P19)+(AO19*$Q19)+($R19)+(AO19*((52+$S19)/52))*(1+$T19))*1/$L19 -> 230802.41 | AS19: =(AP19+(AP19*$J19)+(AP19*$M19)+(AP19*$N19)+(AP19*$O19)+(AP19*$P19)+(AP19*$Q19)+($R19)+(AP19*((52+$S19)/52))*(1+$T19))*1/$L19 -> 292892.39 | AT19: =AQ19/52/$K19 -> 81.111745 | AU19: =AR19/52/$K19 -> 110.9627 | AV19: =AS19/52/$K19 -> 140.81365 | AW19: =($V19*(1+(($U19/100)*3))) -> 66135.748 | AX19: =($W19*(1+(($U19/100)*3))) -> 90475.196 | AY19: =($X19*(1+(($U19/100)*3))) -> 114814.64 | AZ19: =(AW19+(AW19*$J19)+(AW19*$M19)+(AW19*$N19)+(AW19*$O19)+(AW19*$P19)+(AW19*$Q19)+($R19)+(AW19*((52+$S19)/52))*(1+$T19))*1/$L19 -> 168737.73 | BA19: =(AX19+(AX19*$J19)+(AX19*$M19)+(AX19*$N19)+(AX19*$O19)+(AX19*$P19)+(AX19*$Q19)+($R19)+(AX19*((52+$S19)/52))*(1+$T19))*1/$L19 -> 230837.02 | BB19: =(AY19+(AY19*$J19)+(AY19*$M19)+(AY19*$N19)+(AY19*$O19)+(AY19*$P19)+(AY19*$Q19)+($R19)+(AY19*((52+$S19)/52))*(1+$T19))*1/$L19 -> 292936.31 | BC19: =AZ19/52/$K19 -> 81.123908 | BD19: =BA19/52/$K19 -> 110.97934 | BE19: =BB19/52/$K19 -> 140.83477 | BF19: =($V19*(1+(($U19/100)*4))) -> 66145.664 | BG19: =($W19*(1+(($U19/100)*4))) -> 90488.761 | BH19: =($X19*(1+(($U19/100)*4))) -> 114831.86 | BI19: =(BF19+(BF19*$J19)+(BF19*$M19)+(BF19*$N19)+(BF19*$O19)+(BF19*$P19)+(BF19*$Q19)+($R19)+(BF19*((52+$S19)/52))*(1+$T19))*1/$L19 -> 168763.03 | BJ19: =(BG19+(BG19*$J19)+(BG19*$M19)+(BG19*$N19)+(BG19*$O19)+(BG19*$P19)+(BG19*$Q19)+($R19)+(BG19*((52+$S19)/52))*(1+$T19))*1/$L19 -> 230871.63 | BK19: =(BH19+(BH19*$J19)+(BH19*$M19)+(BH19*$N19)+(BH19*$O19)+(BH19*$P19)+(BH19*$Q19)+($R19)+(BH19*((52+$S19)/52))*(1+$T19))*1/$L19 -> 292980.24 | BL19: =BI19/52/$K19 -> 81.136071 | BM19: =BJ19/52/$K19 -> 110.99598 | BN19: =BK19/52/$K19 -> 140.85588
A20: NSW | B20: Pathologists | C20: MP | D20: STAFF SPECIALISTS (STATE) AWARD 2022 | E20: SS1-SS5 | F20: - | G20: - | H20: 179078-241940 | I20: 2022 | J20: 0.105 | K20: 40 | L20: 1 | M20: 0 | N20: 0.035 | O20: 0.2 | P20: 0.174 | Q20: 0.046 | R20: 38000 | S20: 5 | T20: 0.175 | U20: 0.015 | V20: 179078 | W20: =V20+((X20-V20)/2) -> 210509 | X20: 241940 | Y20: =(V20+(V20*$J20)+(V20*$M20)+(V20*$N20)+(V20*$O20)+(V20*$P20)+(V20*$Q20)+($R20)+(V20*((52+$S20)/52))*(1+$T20))*1/$L20 -> 548010.7 | Z20: =(W20+(W20*$J20)+(W20*$M20)+(W20*$N20)+(W20*$O20)+(W20*$P20)+(W20*$Q20)+($R20)+(W20*((52+$S20)/52))*(1+$T20))*1/$L20 -> 637525.58 | AA20: =(X20+(X20*$J20)+(X20*$M20)+(X20*$N20)+(X20*$O20)+(X20*$P20)+(X20*$Q20)+($R20)+(X20*((52+$S20)/52))*(1+$T20))*1/$L20 -> 727040.47 | AB20: =Y20/52/$K20 -> 263.46668 | AC20: =Z20/52/$K20 -> 306.50268 | AD20: =AA20/52/$K20 -> 349.53869 | AE20: =($V20*(1+(($U20/100)*1))) -> 179104.86 | AF20: =($W20*(1+(($U20/100)*1))) -> 210540.58 | AG20: =($X20*(1+(($U20/100)*1))) -> 241976.29 | AH20: =(AE20+(AE20*$J20)+(AE20*$M20)+(AE20*$N20)+(AE20*$O20)+(AE20*$P20)+(AE20*$Q20)+($R20)+(AE20*((52+$S20)/52))*(1+$T20))*1/$L20 -> 548087.2 | AI20: =(AF20+(AF20*$J20)+(AF20*$M20)+(AF20*$N20)+(AF20*$O20)+(AF20*$P20)+(AF20*$Q20)+($R20)+(AF20*((52+$S20)/52))*(1+$T20))*1/$L20 -> 637615.51 | AJ20: =(AG20+(AG20*$J20)+(AG20*$M20)+(AG20*$N20)+(AG20*$O20)+(AG20*$P20)+(AG20*$Q20)+($R20)+(AG20*((52+$S20)/52))*(1+$T20))*1/$L20 -> 727143.82 | AK20: =AH20/52/$K20 -> 263.50346 | AL20: =AI20/52/$K20 -> 306.54592 | AM20: =AJ20/52/$K20 -> 349.58838 | AN20: =($V20*(1+(($U20/100)*2))) -> 179131.72 | AO20: =($W20*(1+(($U20/100)*2))) -> 210572.15 | AP20: =($X20*(1+(($U20/100)*2))) -> 242012.58 | AQ20: =(AN20+(AN20*$J20)+(AN20*$M20)+(AN20*$N20)+(AN20*$O20)+(AN20*$P20)+(AN20*$Q20)+($R20)+(AN20*((52+$S20)/52))*(1+$T20))*1/$L20 -> 548163.7 | AR20: =(AO20+(AO20*$J20)+(AO20*$M20)+(AO20*$N20)+(AO20*$O20)+(AO20*$P20)+(AO20*$Q20)+($R20)+(AO20*((52+$S20)/52))*(1+$T20))*1/$L20 -> 637705.44 | AS20: =(AP20+(AP20*$J20)+(AP20*$M20)+(AP20*$N20)+(AP20*$O20)+(AP20*$P20)+(AP20*$Q20)+($R20)+(AP20*((52+$S20)/52))*(1+$T20))*1/$L20 -> 727247.18 | AT20: =AQ20/52/$K20 -> 263.54024 | AU20: =AR20/52/$K20 -> 306.58915 | AV20: =AS20/52/$K20 -> 349.63807 | AW20: =($V20*(1+(($U20/100)*3))) -> 179158.59 | AX20: =($W20*(1+(($U20/100)*3))) -> 210603.73 | AY20: =($X20*(1+(($U20/100)*3))) -> 242048.87 | AZ20: =(AW20+(AW20*$J20)+(AW20*$M20)+(AW20*$N20)+(AW20*$O20)+(AW20*$P20)+(AW20*$Q20)+($R20)+(AW20*((52+$S20)/52))*(1+$T20))*1/$L20 -> 548240.21 | BA20: =(AX20+(AX20*$J20)+(AX20*$M20)+(AX20*$N20)+(AX20*$O20)+(AX20*$P20)+(AX20*$Q20)+($R20)+(AX20*((52+$S20)/52))*(1+$T20))*1/$L20 -> 637795.37 | BB20: =(AY20+(AY20*$J20)+(AY20*$M20)+(AY20*$N20)+(AY20*$O20)+(AY20*$P20)+(AY20*$Q20)+($R20)+(AY20*((52+$S20)/52))*(1+$T20))*1/$L20 -> 727350.54 | BC20: =AZ20/52/$K20 -> 263.57702 | BD20: =BA20/52/$K20 -> 306.63239 | BE20: =BB20/52/$K20 -> 349.68776 | BF20: =($V20*(1+(($U20/100)*4))) -> 179185.45 | BG20: =($W20*(1+(($U20/100)*4))) -> 210635.31 | BH20: =($X20*(1+(($U20/100)*4))) -> 242085.16 | BI20: =(BF20+(BF20*$J20)+(BF20*$M20)+(BF20*$N20)+(BF20*$O20)+(BF20*$P20)+(BF20*$Q20)+($R20)+(BF20*((52+$S20)/52))*(1+$T20))*1/$L20 -> 548316.71 | BJ20: =(BG20+(BG20*$J20)+(BG20*$M20)+(BG20*$N20)+(BG20*$O20)+(BG20*$P20)+(BG20*$Q20)+($R20)+(BG20*((52+$S20)/52))*(1+$T20))*1/$L20 -> 637885.3 | BK20: =(BH20+(BH20*$J20)+(BH20*$M20)+(BH20*$N20)+(BH20*$O20)+(BH20*$P20)+(BH20*$Q20)+($R20)+(BH20*((52+$S20)/52))*(1+$T20))*1/$L20 -> 727453.89 | BL20: =BI20/52/$K20 -> 263.6138 | BM20: =BJ20/52/$K20 -> 306.67562 | BN20: =BK20/52/$K20 -> 349.73745
A22: QLD | B22: Lab technician | C22: LT | D22: Hospital and Health Service General Employees (Queensland Health) Award - State 2015 | I22: 2022 | J22: 0.1275 | K22: 36.25 | L22: 1 | M22: 0.1 | N22: 0.035 | O22: 0 | P22: 0 | Q22: 0.046 | R22: 1826 | S22: 4 | T22: 0 | U22: 0.015 | V22: 48552 | W22: =V22+((X22-V22)/2) -> 70196 | X22: 91840 | Y22: =(V22+(V22*$J22)+(V22*$M22)+(V22*$N22)+(V22*$O22)+(V22*$P22)+(V22*$Q22)+($R22)+(V22*((52+$S22)/52))*(1+$T22))*1/$L22 -> 117643.06 | Z22: =(W22+(W22*$J22)+(W22*$M22)+(W22*$N22)+(W22*$O22)+(W22*$P22)+(W22*$Q22)+($R22)+(W22*((52+$S22)/52))*(1+$T22))*1/$L22 -> 169273.16 | AA22: =(X22+(X22*$J22)+(X22*$M22)+(X22*$N22)+(X22*$O22)+(X22*$P22)+(X22*$Q22)+($R22)+(X22*((52+$S22)/52))*(1+$T22))*1/$L22 -> 220903.26 | AB22: =Y22/52/$K22 -> 62.410112 | AC22: =Z22/52/$K22 -> 89.800084 | AD22: =AA22/52/$K22 -> 117.19006 | AE22: =($V22*(1+(($U22/100)*1))) -> 48559.283 | AF22: =($W22*(1+(($U22/100)*1))) -> 70206.529 | AG22: =($X22*(1+(($U22/100)*1))) -> 91853.776 | AH22: =(AE22+(AE22*$J22)+(AE22*$M22)+(AE22*$N22)+(AE22*$O22)+(AE22*$P22)+(AE22*$Q22)+($R22)+(AE22*((52+$S22)/52))*(1+$T22))*1/$L22 -> 117660.43 | AI22: =(AF22+(AF22*$J22)+(AF22*$M22)+(AF22*$N22)+(AF22*$O22)+(AF22*$P22)+(AF22*$Q22)+($R22)+(AF22*((52+$S22)/52))*(1+$T22))*1/$L22 -> 169298.28 | AJ22: =(AG22+(AG22*$J22)+(AG22*$M22)+(AG22*$N22)+(AG22*$O22)+(AG22*$P22)+(AG22*$Q22)+($R22)+(AG22*((52+$S22)/52))*(1+$T22))*1/$L22 -> 220936.12 | AK22: =AH22/52/$K22 -> 62.419328 | AL22: =AI22/52/$K22 -> 89.813409 | AM22: =AJ22/52/$K22 -> 117.20749 | AN22: =($V22*(1+(($U22/100)*2))) -> 48566.566 | AO22: =($W22*(1+(($U22/100)*2))) -> 70217.059 | AP22: =($X22*(1+(($U22/100)*2))) -> 91867.552 | AQ22: =(AN22+(AN22*$J22)+(AN22*$M22)+(AN22*$N22)+(AN22*$O22)+(AN22*$P22)+(AN22*$Q22)+($R22)+(AN22*((52+$S22)/52))*(1+$T22))*1/$L22 -> 117677.81 | AR22: =(AO22+(AO22*$J22)+(AO22*$M22)+(AO22*$N22)+(AO22*$O22)+(AO22*$P22)+(AO22*$Q22)+($R22)+(AO22*((52+$S22)/52))*(1+$T22))*1/$L22 -> 169323.39 | AS22: =(AP22+(AP22*$J22)+(AP22*$M22)+(AP22*$N22)+(AP22*$O22)+(AP22*$P22)+(AP22*$Q22)+($R22)+(AP22*((52+$S22)/52))*(1+$T22))*1/$L22 -> 220968.98 | AT22: =AQ22/52/$K22 -> 62.428544 | AU22: =AR22/52/$K22 -> 89.826733 | AV22: =AS22/52/$K22 -> 117.22492 | AW22: =($V22*(1+(($U22/100)*3))) -> 48573.848 | AX22: =($W22*(1+(($U22/100)*3))) -> 70227.588 | AY22: =($X22*(1+(($U22/100)*3))) -> 91881.328 | AZ22: =(AW22+(AW22*$J22)+(AW22*$M22)+(AW22*$N22)+(AW22*$O22)+(AW22*$P22)+(AW22*$Q22)+($R22)+(AW22*((52+$S22)/52))*(1+$T22))*1/$L22 -> 117695.18 | BA22: =(AX22+(AX22*$J22)+(AX22*$M22)+(AX22*$N22)+(AX22*$O22)+(AX22*$P22)+(AX22*$Q22)+($R22)+(AX22*((52+$S22)/52))*(1+$T22))*1/$L22 -> 169348.51 | BB22: =(AY22+(AY22*$J22)+(AY22*$M22)+(AY22*$N22)+(AY22*$O22)+(AY22*$P22)+(AY22*$Q22)+($R22)+(AY22*((52+$S22)/52))*(1+$T22))*1/$L22 -> 221001.84 | BC22: =AZ22/52/$K22 -> 62.437761 | BD22: =BA22/52/$K22 -> 89.840058 | BE22: =BB22/52/$K22 -> 117.24236 | BF22: =($V22*(1+(($U22/100)*4))) -> 48581.131 | BG22: =($W22*(1+(($U22/100)*4))) -> 70238.118 | BH22: =($X22*(1+(($U22/100)*4))) -> 91895.104 | BI22: =(BF22+(BF22*$J22)+(BF22*$M22)+(BF22*$N22)+(BF22*$O22)+(BF22*$P22)+(BF22*$Q22)+($R22)+(BF22*((52+$S22)/52))*(1+$T22))*1/$L22 -> 117712.55 | BJ22: =(BG22+(BG22*$J22)+(BG22*$M22)+(BG22*$N22)+(BG22*$O22)+(BG22*$P22)+(BG22*$Q22)+($R22)+(BG22*((52+$S22)/52))*(1+$T22))*1/$L22 -> 169373.63 | BK22: =(BH22+(BH22*$J22)+(BH22*$M22)+(BH22*$N22)+(BH22*$O22)+(BH22*$P22)+(BH22*$Q22)+($R22)+(BH22*((52+$S22)/52))*(1+$T22))*1/$L22 -> 221034.7 | BL22: =BI22/52/$K22 -> 62.446977 | BM22: =BJ22/52/$K22 -> 89.853383 | BN22: =BK22/52/$K22 -> 117.25979
